Workbook

Sheet CAPACIDADE
A1: ETAPAS | B1: PEDIDOS EM CARTEIRA
B2: ESTRUTURA | C2: USINAGEM | D2: TAMBOR | E2: ROLOS | F2: BASES ROLETES | G2: REVESTIMENTO | H2: AXION | I2: CARGA TOTAL
A3: CARGA TOTAL PROGRAMADA
A4: PEDENTE DE FABRICAÇÃO
A6: PRONTO ACABADO
A7: PESO EXPEDIDO
A8: PEDENTE DE EXPEDIÇÃO
A9: CAPACIDADE (TON) | B9: 20 | C9: 10 | D9: 15 | E9: 8 | F9: 5 | G9: 7 | H9: 20 | I9: 0

Sheet MICRO
A1: DESENHO MDE | B1: DESENHO CLIENTE | C1: QTE | D1: DESCRIÇÃO | E1: COD.MDE | F1: REMESSA | G1: PESO UNI | H1: PESO TOTAL | I1: Revisão | J1: TAG | K1: PRODUTO | L1: PEDIDO | M1: Engenharia | N1: FORNECEDOR | O1: QTDE/ Fabricação | P1: DATA/Fabricação | Q1: SALDO PENDENTE/Fabricação | R1: EVOLUÇÃO PRETO / Fabricação (kg) | S1: PRONTO ACABADO kg | T1: Pendencia / Fabricação EM KG | U1: QIANTIDADE EXPEDIDA | V1: ROMANEIO | W1: DATA EXPEDIÇÃO | X1: Peso Expedido | Y1: QUANTIDADE PENDENTE/Expedição | Z1: PESO PENDENTE/Expedição | AA1: MATÉRIA PRIMA | AB1: RELATORIO | AC1: PREPARAÇÃO | AD1: CALDEIRARIA | AE1: SOLDA | AF1: ACABAMENTO | AG1: PRONTO ACABADO | AH1: EXPEDIÇÃO | AI1: FINALIZADO | AJ1: Coluna1 | AK1: Coluna2 | AL1: Coluna3 | AM1: Coluna4 | AN1: x | AO1: Colunas5 | AP1: Colunas6 | AQ1: Colunas7 | AR1: Coluna5 | AS1: PRONTO NO PRETO | AT1: PRONTO ACABADO3 | AU1: PESO EXPEDIDO2 | AV1: PRONTO ACABADO2 | AW1: Coluna7
A2: T-060864-1 | C2: 39 | D2: BASE DE ROLETE COMPLETA 60864A | E2: 3392 | F2: 8 | G2: 15.8 | H2: =Tabela1[[#This Row],[PESO UNI]]*Tabela1[[#This Row],[QTE]] -> 616.2 | I2: 0 | J2: 1073-TC-006 | K2: BASES ROLETES | L2: P-188 | M2: 46100 | N2: MDE | Q2: =Tabela1[[#This Row],[QTDE/ Fabricação]]-Tabela1[[#This Row],[QTE]] -> -39 | R2: =IFERROR(H2*((AA2*0.25)+(AC2*0.25)+(AD2*0.225)+(AE2*0.225)+(AF2*0.05)),"") -> 616.2 | S2: =IFERROR(H2*AG2,"") -> 616.2 | T2: =IFERROR(S2-H2,"") -> 0 | U2: =IFERROR(SUMIF('LISTA DE EMBARQUE'!B:B,MICRO!E:E,'LISTA DE EMBARQUE'!G:G),"") -> 38 | V2: =IFERROR(VLOOKUP(Tabela1[[#This Row],[COD.MDE]],'LISTA DE EMBARQUE'!B:L,11,0),"") -> 1 | W2: =IFERROR(VLOOKUP(Tabela1[[#This Row],[COD.MDE]],'LISTA DE EMBARQUE'!B:M,12,0),"") -> 46146 | X2: =IFERROR(Tabela1[[#This Row],[QIANTIDADE EXPEDIDA]]*Tabela1[[#This Row],[PESO UNI]],"") -> 600.4 | Y2: =U2-C2 -> -1 | Z2: =Tabela1[[#This Row],[PESO TOTAL]]-Tabela1[[#This Row],[Peso Expedido]] -> 15.8 | AA2: 1 | AB2: 1 | AC2: 1 | AD2: 1 | AE2: 1 | AF2: 1 | AG2: 1 | AH2: 1 | AI2: OK | AK2: =Tabela1[[#This Row],[Coluna1]]&Tabela1[[#This Row],[PEDIDO]] -> P-188 | AO2: =A2&"/"&J2 -> T-060864-1/1073-TC-006 | AP2: =Tabela1[[#This Row],[TAG]]&Tabela1[[#This Row],[PEDIDO]]&Tabela1[[#This Row],[PRODUTO]] -> 1073-TC-006P-188BASES ROLETES | AQ2: =Tabela1[[#This Row],[PRODUTO]]&Tabela1[[#This Row],[TAG]] -> BASES ROLETES1073-TC-006 | AR2: =Tabela1[[#This Row],[PEDIDO]]&Tabela1[[#This Row],[PRODUTO]] -> P-188BASES ROLETES | AS2: =IF(AF2="",0,IF(ISTEXT(AF2),H2*VALUE(SUBSTITUTE(AF2,"%",""))/100,H2*AF2))-Tabela1[[#This Row],[PRONTO ACABADO2]] -> 0 | AT2: =IF(AG2="",0,IF(ISTEXT(AG2),H2*VALUE(SUBSTITUTE(AG2,"%",""))/100,H2*AG2))-Tabela1[[#This Row],[PESO EXPEDIDO2]] -> 0 | AU2: =IF(AH2="",0,IF(ISTEXT(AH2),H2*VALUE(SUBSTITUTE(AH2,"%",""))/100,H2*AH2)) -> 616.2 | AV2: =IF(AG2="",0,IF(ISTEXT(AG2),H2*VALUE(SUBSTITUTE(AG2,"%",""))/100,H2*AG2)) -> 616.2
A3: T-060864-1 | C3: 39 | D3: BASE DE ROLETE COMPLETA 60864A | E3: 3393 | F3: 8 | G3: 15.8 | H3: =Tabela1[[#This Row],[PESO UNI]]*Tabela1[[#This Row],[QTE]] -> 616.2 | I3: 0 | J3: 1073-TC-007 | K3: BASES ROLETES | L3: P-188 | M3: 46100 | N3: MDE | Q3: =Tabela1[[#This Row],[QTDE/ Fabricação]]-Tabela1[[#This Row],[QTE]] -> -39 | R3: =IFERROR(H3*((AA3*0.25)+(AC3*0.25)+(AD3*0.225)+(AE3*0.225)+(AF3*0.05)),"") -> 616.2 | S3: =IFERROR(H3*AG3,"") -> 616.2 | T3: =IFERROR(S3-H3,"") -> 0 | U3: =IFERROR(SUMIF('LISTA DE EMBARQUE'!B:B,MICRO!E:E,'LISTA DE EMBARQUE'!G:G),"") -> 38 | V3: =IFERROR(VLOOKUP(Tabela1[[#This Row],[COD.MDE]],'LISTA DE EMBARQUE'!B:L,11,0),"") -> 1 | W3: =IFERROR(VLOOKUP(Tabela1[[#This Row],[COD.MDE]],'LISTA DE EMBARQUE'!B:M,12,0),"") -> 46146 | X3: =IFERROR(Tabela1[[#This Row],[QIANTIDADE EXPEDIDA]]*Tabela1[[#This Row],[PESO UNI]],"") -> 600.4 | Y3: =U3-C3 -> -1 | Z3: =Tabela1[[#This Row],[PESO TOTAL]]-Tabela1[[#This Row],[Peso Expedido]] -> 15.8 | AA3: 1 | AB3: 1 | AC3: 1 | AD3: 1 | AE3: 1 | AF3: 1 | AG3: 1 | AH3: 1 | AI3: OK | AK3: =Tabela1[[#This Row],[Coluna1]]&Tabela1[[#This Row],[PEDIDO]] -> P-188 | AO3: =A3&"/"&J3 -> T-060864-1/1073-TC-007 | AP3: =Tabela1[[#This Row],[TAG]]&Tabela1[[#This Row],[PEDIDO]]&Tabela1[[#This Row],[PRODUTO]] -> 1073-TC-007P-188BASES ROLETES | AQ3: =Tabela1[[#This Row],[PRODUTO]]&Tabela1[[#This Row],[TAG]] -> BASES ROLETES1073-TC-007 | AR3: =Tabela1[[#This Row],[PEDIDO]]&Tabela1[[#This Row],[PRODUTO]] -> P-188BASES ROLETES | AS3: =IF(AF3="",0,IF(ISTEXT(AF3),H3*VALUE(SUBSTITUTE(AF3,"%",""))/100,H3*AF3))-Tabela1[[#This Row],[PRONTO ACABADO2]] -> 0 | AT3: =IF(AG3="",0,IF(ISTEXT(AG3),H3*VALUE(SUBSTITUTE(AG3,"%",""))/100,H3*AG3))-Tabela1[[#This Row],[PESO EXPEDIDO2]] -> 0 | AU3: =IF(AH3="",0,IF(ISTEXT(AH3),H3*VALUE(SUBSTITUTE(AH3,"%",""))/100,H3*AH3)) -> 616.2 | AV3: =IF(AG3="",0,IF(ISTEXT(AG3),H3*VALUE(SUBSTITUTE(AG3,"%",""))/100,H3*AG3)) -> 616.2
A4: T-060860-1 | C4: 1 | D4: BASE DE ROLETE P/ BALANÇA 60860A | E4: 3394 | F4: 8 | G4: 19.2 | H4: =Tabela1[[#This Row],[PESO UNI]]*Tabela1[[#This Row],[QTE]] -> 19.2 | I4: 0 | J4: 1073-TC-006 | K4: BASES ROLETES | L4: P-188 | M4: 46100 | N4: MDE | Q4: =Tabela1[[#This Row],[QTDE/ Fabricação]]-Tabela1[[#This Row],[QTE]] -> -1 | R4: =IFERROR(H4*((AA4*0.25)+(AC4*0.25)+(AD4*0.225)+(AE4*0.225)+(AF4*0.05)),"") -> 19.2 | S4: =IFERROR(H4*AG4,"") -> 19.2 | T4: =IFERROR(S4-H4,"") -> 0 | U4: =IFERROR(SUMIF('LISTA DE EMBARQUE'!B:B,MICRO!E:E,'LISTA DE EMBARQUE'!G:G),"") -> 1 | V4: =IFERROR(VLOOKUP(Tabela1[[#This Row],[COD.MDE]],'LISTA DE EMBARQUE'!B:L,11,0),"") -> 1 | W4: =IFERROR(VLOOKUP(Tabela1[[#This Row],[COD.MDE]],'LISTA DE EMBARQUE'!B:M,12,0),"") -> 46146 | X4: =IFERROR(Tabela1[[#This Row],[QIANTIDADE EXPEDIDA]]*Tabela1[[#This Row],[PESO UNI]],"") -> 19.2 | Y4: =U4-C4 -> 0 | Z4: =Tabela1[[#This Row],[PESO TOTAL]]-Tabela1[[#This Row],[Peso Expedido]] -> 0 | AA4: 1 | AB4: 1 | AC4: 1 | AD4: 1 | AE4: 1 | AF4: 1 | AG4: 1 | AH4: 1 | AI4: =IF(Z4<=0,"ok","") -> ok | AK4: =Tabela1[[#This Row],[Coluna1]]&Tabela1[[#This Row],[PEDIDO]] -> P-188 | AO4: =A4&"/"&J4 -> T-060860-1/1073-TC-006 | AP4: =Tabela1[[#This Row],[TAG]]&Tabela1[[#This Row],[PEDIDO]]&Tabela1[[#This Row],[PRODUTO]] -> 1073-TC-006P-188BASES ROLETES | AQ4: =Tabela1[[#This Row],[PRODUTO]]&Tabela1[[#This Row],[TAG]] -> BASES ROLETES1073-TC-006 | AR4: =Tabela1[[#This Row],[PEDIDO]]&Tabela1[[#This Row],[PRODUTO]] -> P-188BASES ROLETES | AS4: =IF(AF4="",0,IF(ISTEXT(AF4),H4*VALUE(SUBSTITUTE(AF4,"%",""))/100,H4*AF4))-Tabela1[[#This Row],[PRONTO ACABADO2]] -> 0 | AT4: =IF(AG4="",0,IF(ISTEXT(AG4),H4*VALUE(SUBSTITUTE(AG4,"%",""))/100,H4*AG4))-Tabela1[[#This Row],[PESO EXPEDIDO2]] -> 0 | AU4: =IF(AH4="",0,IF(ISTEXT(AH4),H4*VALUE(SUBSTITUTE(AH4,"%",""))/100,H4*AH4)) -> 19.2 | AV4: =IF(AG4="",0,IF(ISTEXT(AG4),H4*VALUE(SUBSTITUTE(AG4,"%",""))/100,H4*AG4)) -> 19.2
A5: T-060860-1 | C5: 1 | D5: BASE DE ROLETE P/ BALANÇA 60860A | E5: 3395 | F5: 8 | G5: 19.2 | H5: =Tabela1[[#This Row],[PESO UNI]]*Tabela1[[#This Row],[QTE]] -> 19.2 | I5: 0 | J5: 1073-TC-007 | K5: BASES ROLETES | L5: P-188 | M5: 46100 | N5: MDE | Q5: =Tabela1[[#This Row],[QTDE/ Fabricação]]-Tabela1[[#This Row],[QTE]] -> -1 | R5: =IFERROR(H5*((AA5*0.25)+(AC5*0.25)+(AD5*0.225)+(AE5*0.225)+(AF5*0.05)),"") -> 19.2 | S5: =IFERROR(H5*AG5,"") -> 19.2 | T5: =IFERROR(S5-H5,"") -> 0 | U5: =IFERROR(SUMIF('LISTA DE EMBARQUE'!B:B,MICRO!E:E,'LISTA DE EMBARQUE'!G:G),"") -> 1 | V5: =IFERROR(VLOOKUP(Tabela1[[#This Row],[COD.MDE]],'LISTA DE EMBARQUE'!B:L,11,0),"") -> 1 | W5: =IFERROR(VLOOKUP(Tabela1[[#This Row],[COD.MDE]],'LISTA DE EMBARQUE'!B:M,12,0),"") -> 46146 | X5: =IFERROR(Tabela1[[#This Row],[QIANTIDADE EXPEDIDA]]*Tabela1[[#This Row],[PESO UNI]],"") -> 19.2 | Y5: =U5-C5 -> 0 | Z5: =Tabela1[[#This Row],[PESO TOTAL]]-Tabela1[[#This Row],[Peso Expedido]] -> 0 | AA5: 1 | AB5: 1 | AC5: 1 | AD5: 1 | AE5: 1 | AF5: 1 | AG5: 1 | AH5: 1 | AI5: =IF(Z5<=0,"ok","") -> ok | AK5: =Tabela1[[#This Row],[Coluna1]]&Tabela1[[#This Row],[PEDIDO]] -> P-188 | AO5: =A5&"/"&J5 -> T-060860-1/1073-TC-007 | AP5: =Tabela1[[#This Row],[TAG]]&Tabela1[[#This Row],[PEDIDO]]&Tabela1[[#This Row],[PRODUTO]] -> 1073-TC-007P-188BASES ROLETES | AQ5: =Tabela1[[#This Row],[PRODUTO]]&Tabela1[[#This Row],[TAG]] -> BASES ROLETES1073-TC-007 | AR5: =Tabela1[[#This Row],[PEDIDO]]&Tabela1[[#This Row],[PRODUTO]] -> P-188BASES ROLETES | AS5: =IF(AF5="",0,IF(ISTEXT(AF5),H5*VALUE(SUBSTITUTE(AF5,"%",""))/100,H5*AF5))-Tabela1[[#This Row],[PRONTO ACABADO2]] -> 0 | AT5: =IF(AG5="",0,IF(ISTEXT(AG5),H5*VALUE(SUBSTITUTE(AG5,"%",""))/100,H5*AG5))-Tabela1[[#This Row],[PESO EXPEDIDO2]] -> 0 | AU5: =IF(AH5="",0,IF(ISTEXT(AH5),H5*VALUE(SUBSTITUTE(AH5,"%",""))/100,H5*AH5)) -> 19.2 | AV5: =IF(AG5="",0,IF(ISTEXT(AG5),H5*VALUE(SUBSTITUTE(AG5,"%",""))/100,H5*AG5)) -> 19.2
A6: T-052878-1 | C6: 4 | D6: BASE PARA ROLO DE PROTEÇÃO 52878A | E6: 3396 | F6: 8 | G6: 2.7 | H6: =Tabela1[[#This Row],[PESO UNI]]*Tabela1[[#This Row],[QTE]] -> 10.8 | I6: 1 | J6: 1073-TC-006 | K6: BASES ROLETES | L6: P-188 | M6: 46100 | N6: MDE | Q6: =Tabela1[[#This Row],[QTDE/ Fabricação]]-Tabela1[[#This Row],[QTE]] -> -4 | R6: =IFERROR(H6*((AA6*0.25)+(AC6*0.25)+(AD6*0.225)+(AE6*0.225)+(AF6*0.05)),"") -> 10.8 | S6: =IFERROR(H6*AG6,"") -> 10.8 | T6: =IFERROR(S6-H6,"") -> 0 | U6: =IFERROR(SUMIF('LISTA DE EMBARQUE'!B:B,MICRO!E:E,'LISTA DE EMBARQUE'!G:G),"") -> 4 | V6: =IFERROR(VLOOKUP(Tabela1[[#This Row],[COD.MDE]],'LISTA DE EMBARQUE'!B:L,11,0),"") -> 1 | W6: =IFERROR(VLOOKUP(Tabela1[[#This Row],[COD.MDE]],'LISTA DE EMBARQUE'!B:M,12,0),"") -> 46146 | X6: =IFERROR(Tabela1[[#This Row],[QIANTIDADE EXPEDIDA]]*Tabela1[[#This Row],[PESO UNI]],"") -> 10.8 | Y6: =U6-C6 -> 0 | Z6: =Tabela1[[#This Row],[PESO TOTAL]]-Tabela1[[#This Row],[Peso Expedido]] -> 0 | AA6: 1 | AB6: 1 | AC6: 1 | AD6: 1 | AE6: 1 | AF6: 1 | AG6: 1 | AH6: 1 | AI6: =IF(Z6<=0,"ok","") -> ok | AK6: =Tabela1[[#This Row],[Coluna1]]&Tabela1[[#This Row],[PEDIDO]] -> P-188 | AO6: =A6&"/"&J6 -> T-052878-1/1073-TC-006 | AP6: =Tabela1[[#This Row],[TAG]]&Tabela1[[#This Row],[PEDIDO]]&Tabela1[[#This Row],[PRODUTO]] -> 1073-TC-006P-188BASES ROLETES | AQ6: =Tabela1[[#This Row],[PRODUTO]]&Tabela1[[#This Row],[TAG]] -> BASES ROLETES1073-TC-006 | AR6: =Tabela1[[#This Row],[PEDIDO]]&Tabela1[[#This Row],[PRODUTO]] -> P-188BASES ROLETES | AS6: =IF(AF6="",0,IF(ISTEXT(AF6),H6*VALUE(SUBSTITUTE(AF6,"%",""))/100,H6*AF6))-Tabela1[[#This Row],[PRONTO ACABADO2]] -> 0 | AT6: =IF(AG6="",0,IF(ISTEXT(AG6),H6*VALUE(SUBSTITUTE(AG6,"%",""))/100,H6*AG6))-Tabela1[[#This Row],[PESO EXPEDIDO2]] -> 0 | AU6: =IF(AH6="",0,IF(ISTEXT(AH6),H6*VALUE(SUBSTITUTE(AH6,"%",""))/100,H6*AH6)) -> 10.8 | AV6: =IF(AG6="",0,IF(ISTEXT(AG6),H6*VALUE(SUBSTITUTE(AG6,"%",""))/100,H6*AG6)) -> 10.8
A7: T-052878-1 | C7: 4 | D7: BASE PARA ROLO DE PROTEÇÃO 52878A | E7: 3397 | F7: 8 | G7: 2.7 | H7: =Tabela1[[#This Row],[PESO UNI]]*Tabela1[[#This Row],[QTE]] -> 10.8 | I7: 1 | J7: 1073-TC-007 | K7: BASES ROLETES | L7: P-188 | M7: 46100 | N7: MDE | Q7: =Tabela1[[#This Row],[QTDE/ Fabricação]]-Tabela1[[#This Row],[QTE]] -> -4 | R7: =IFERROR(H7*((AA7*0.25)+(AC7*0.25)+(AD7*0.225)+(AE7*0.225)+(AF7*0.05)),"") -> 10.8 | S7: =IFERROR(H7*AG7,"") -> 10.8 | T7: =IFERROR(S7-H7,"") -> 0 | U7: =IFERROR(SUMIF('LISTA DE EMBARQUE'!B:B,MICRO!E:E,'LISTA DE EMBARQUE'!G:G),"") -> 4 | V7: =IFERROR(VLOOKUP(Tabela1[[#This Row],[COD.MDE]],'LISTA DE EMBARQUE'!B:L,11,0),"") -> 1 | W7: =IFERROR(VLOOKUP(Tabela1[[#This Row],[COD.MDE]],'LISTA DE EMBARQUE'!B:M,12,0),"") -> 46146 | X7: =IFERROR(Tabela1[[#This Row],[QIANTIDADE EXPEDIDA]]*Tabela1[[#This Row],[PESO UNI]],"") -> 10.8 | Y7: =U7-C7 -> 0 | Z7: =Tabela1[[#This Row],[PESO TOTAL]]-Tabela1[[#This Row],[Peso Expedido]] -> 0 | AA7: 1 | AB7: 1 | AC7: 1 | AD7: 1 | AE7: 1 | AF7: 1 | AG7: 1 | AH7: 1 | AI7: =IF(Z7<=0,"ok","") -> ok | AK7: =Tabela1[[#This Row],[Coluna1]]&Tabela1[[#This Row],[PEDIDO]] -> P-188 | AO7: =A7&"/"&J7 -> T-052878-1/1073-TC-007 | AP7: =Tabela1[[#This Row],[TAG]]&Tabela1[[#This Row],[PEDIDO]]&Tabela1[[#This Row],[PRODUTO]] -> 1073-TC-007P-188BASES ROLETES | AQ7: =Tabela1[[#This Row],[PRODUTO]]&Tabela1[[#This Row],[TAG]] -> BASES ROLETES1073-TC-007 | AR7: =Tabela1[[#This Row],[PEDIDO]]&Tabela1[[#This Row],[PRODUTO]] -> P-188BASES ROLETES | AS7: =IF(AF7="",0,IF(ISTEXT(AF7),H7*VALUE(SUBSTITUTE(AF7,"%",""))/100,H7*AF7))-Tabela1[[#This Row],[PRONTO ACABADO2]] -> 0 | AT7: =IF(AG7="",0,IF(ISTEXT(AG7),H7*VALUE(SUBSTITUTE(AG7,"%",""))/100,H7*AG7))-Tabela1[[#This Row],[PESO EXPEDIDO2]] -> 0 | AU7: =IF(AH7="",0,IF(ISTEXT(AH7),H7*VALUE(SUBSTITUTE(AH7,"%",""))/100,H7*AH7)) -> 10.8 | AV7: =IF(AG7="",0,IF(ISTEXT(AG7),H7*VALUE(SUBSTITUTE(AG7,"%",""))/100,H7*AG7)) -> 10.8
A8: R-007180-1 | C8: 2 | D8: BASE AA RETORNO 7180A | E8: 3398 | F8: 8 | G8: 68.1 | H8: =Tabela1[[#This Row],[PESO UNI]]*Tabela1[[#This Row],[QTE]] -> 136.2 | I8: 1 | J8: 1073-TC-006 | K8: BASES ROLETES | L8: P-188 | M8: 46226 | N8: MDE | Q8: =Tabela1[[#This Row],[QTDE/ Fabricação]]-Tabela1[[#This Row],[QTE]] -> -2 | R8: =IFERROR(H8*((AA8*0.25)+(AC8*0.25)+(AD8*0.225)+(AE8*0.225)+(AF8*0.05)),"") -> 136.2 | S8: =IFERROR(H8*AG8,"") -> 136.2 | T8: =IFERROR(S8-H8,"") -> 0 | U8: =IFERROR(SUMIF('LISTA DE EMBARQUE'!B:B,MICRO!E:E,'LISTA DE EMBARQUE'!G:G),"") -> 2 | V8: =IFERROR(VLOOKUP(Tabela1[[#This Row],[COD.MDE]],'LISTA DE EMBARQUE'!B:L,11,0),"") -> 4 | W8: =IFERROR(VLOOKUP(Tabela1[[#This Row],[COD.MDE]],'LISTA DE EMBARQUE'!B:M,12,0),"") -> 46174 | X8: =IFERROR(Tabela1[[#This Row],[QIANTIDADE EXPEDIDA]]*Tabela1[[#This Row],[PESO UNI]],"") -> 136.2 | Y8: =U8-C8 -> 0 | Z8: =Tabela1[[#This Row],[PESO TOTAL]]-Tabela1[[#This Row],[Peso Expedido]] -> 0 | AA8: 1 | AB8: 1 | AC8: 1 | AD8: 1 | AE8: 1 | AF8: 1 | AG8: 1 | AH8: 1 | AI8: ok | AK8: =Tabela1[[#This Row],[Coluna1]]&Tabela1[[#This Row],[PEDIDO]] -> P-188 | AO8: =A8&"/"&J8 -> R-007180-1/1073-TC-006 | AP8: =Tabela1[[#This Row],[TAG]]&Tabela1[[#This Row],[PEDIDO]]&Tabela1[[#This Row],[PRODUTO]] -> 1073-TC-006P-188BASES ROLETES | AQ8: =Tabela1[[#This Row],[PRODUTO]]&Tabela1[[#This Row],[TAG]] -> BASES ROLETES1073-TC-006 | AR8: =Tabela1[[#This Row],[PEDIDO]]&Tabela1[[#This Row],[PRODUTO]] -> P-188BASES ROLETES | AS8: =IF(AF8="",0,IF(ISTEXT(AF8),H8*VALUE(SUBSTITUTE(AF8,"%",""))/100,H8*AF8))-Tabela1[[#This Row],[PRONTO ACABADO2]] -> 0 | AT8: =IF(AG8="",0,IF(ISTEXT(AG8),H8*VALUE(SUBSTITUTE(AG8,"%",""))/100,H8*AG8))-Tabela1[[#This Row],[PESO EXPEDIDO2]] -> 0 | AU8: =IF(AH8="",0,IF(ISTEXT(AH8),H8*VALUE(SUBSTITUTE(AH8,"%",""))/100,H8*AH8)) -> 136.2 | AV8: =IF(AG8="",0,IF(ISTEXT(AG8),H8*VALUE(SUBSTITUTE(AG8,"%",""))/100,H8*AG8)) -> 136.2
A9: R-007180-1 | C9: 2 | D9: BASE AA RETORNO 7180A | E9: 3399 | F9: 8 | G9: 68.1 | H9: =Tabela1[[#This Row],[PESO UNI]]*Tabela1[[#This Row],[QTE]] -> 136.2 | I9: 1 | J9: 1073-TC-007 | K9: BASES ROLETES | L9: P-188 | M9: 46226 | N9: MDE | Q9: =Tabela1[[#This Row],[QTDE/ Fabricação]]-Tabela1[[#This Row],[QTE]] -> -2 | R9: =IFERROR(H9*((AA9*0.25)+(AC9*0.25)+(AD9*0.225)+(AE9*0.225)+(AF9*0.05)),"") -> 136.2 | S9: =IFERROR(H9*AG9,"") -> 136.2 | T9: =IFERROR(S9-H9,"") -> 0 | U9: =IFERROR(SUMIF('LISTA DE EMBARQUE'!B:B,MICRO!E:E,'LISTA DE EMBARQUE'!G:G),"") -> 2 | V9: =IFERROR(VLOOKUP(Tabela1[[#This Row],[COD.MDE]],'LISTA DE EMBARQUE'!B:L,11,0),"") -> 4 | W9: =IFERROR(VLOOKUP(Tabela1[[#This Row],[COD.MDE]],'LISTA DE EMBARQUE'!B:M,12,0),"") -> 46174 | X9: =IFERROR(Tabela1[[#This Row],[QIANTIDADE EXPEDIDA]]*Tabela1[[#This Row],[PESO UNI]],"") -> 136.2 | Y9: =U9-C9 -> 0 | Z9: =Tabela1[[#This Row],[PESO TOTAL]]-Tabela1[[#This Row],[Peso Expedido]] -> 0 | AA9: 1 | AB9: 1 | AC9: 1 | AD9: 1 | AE9: 1 | AF9: 1 | AG9: 1 | AH9: 1 | AI9: ok | AK9: =Tabela1[[#This Row],[Coluna1]]&Tabela1[[#This Row],[PEDIDO]] -> P-188 | AO9: =A9&"/"&J9 -> R-007180-1/1073-TC-007 | AP9: =Tabela1[[#This Row],[TAG]]&Tabela1[[#This Row],[PEDIDO]]&Tabela1[[#This Row],[PRODUTO]] -> 1073-TC-007P-188BASES ROLETES | AQ9: =Tabela1[[#This Row],[PRODUTO]]&Tabela1[[#This Row],[TAG]] -> BASES ROLETES1073-TC-007 | AR9: =Tabela1[[#This Row],[PEDIDO]]&Tabela1[[#This Row],[PRODUTO]] -> P-188BASES ROLETES | AS9: =IF(AF9="",0,IF(ISTEXT(AF9),H9*VALUE(SUBSTITUTE(AF9,"%",""))/100,H9*AF9))-Tabela1[[#This Row],[PRONTO ACABADO2]] -> 0 | AT9: =IF(AG9="",0,IF(ISTEXT(AG9),H9*VALUE(SUBSTITUTE(AG9,"%",""))/100,H9*AG9))-Tabela1[[#This Row],[PESO EXPEDIDO2]] -> 0 | AU9: =IF(AH9="",0,IF(ISTEXT(AH9),H9*VALUE(SUBSTITUTE(AH9,"%",""))/100,H9*AH9)) -> 136.2 | AV9: =IF(AG9="",0,IF(ISTEXT(AG9),H9*VALUE(SUBSTITUTE(AG9,"%",""))/100,H9*AG9)) -> 136.2
A10: T-007179-4 | C10: 9 | D10: BASE DE RETORNO 7179A | E10: 3400 | F10: 8 | G10: 5.7 | H10: =Tabela1[[#This Row],[PESO UNI]]*Tabela1[[#This Row],[QTE]] -> 51.3 | I10: 0 | J10: 1073-TC-006 | K10: BASES ROLETES | L10: P-188 | M10: 46100 | N10: MDE | Q10: =Tabela1[[#This Row],[QTDE/ Fabricação]]-Tabela1[[#This Row],[QTE]] -> -9 | R10: =IFERROR(H10*((AA10*0.25)+(AC10*0.25)+(AD10*0.225)+(AE10*0.225)+(AF10*0.05)),"") -> 51.3 | S10: =IFERROR(H10*AG10,"") -> 51.3 | T10: =IFERROR(S10-H10,"") -> 0 | U10: =IFERROR(SUMIF('LISTA DE EMBARQUE'!B:B,MICRO!E:E,'LISTA DE EMBARQUE'!G:G),"") -> 9 | V10: =IFERROR(VLOOKUP(Tabela1[[#This Row],[COD.MDE]],'LISTA DE EMBARQUE'!B:L,11,0),"") -> 1 | W10: =IFERROR(VLOOKUP(Tabela1[[#This Row],[COD.MDE]],'LISTA DE EMBARQUE'!B:M,12,0),"") -> 46146 | X10: =IFERROR(Tabela1[[#This Row],[QIANTIDADE EXPEDIDA]]*Tabela1[[#This Row],[PESO UNI]],"") -> 51.3 | Y10: =U10-C10 -> 0 | Z10: =Tabela1[[#This Row],[PESO TOTAL]]-Tabela1[[#This Row],[Peso Expedido]] -> 0 | AA10: 1 | AB10: 1 | AC10: 1 | AD10: 1 | AE10: 1 | AF10: 1 | AG10: 1 | AH10: 1 | AI10: =IF(Z10<=0,"ok","") -> ok | AK10: =Tabela1[[#This Row],[Coluna1]]&Tabela1[[#This Row],[PEDIDO]] -> P-188 | AO10: =A10&"/"&J10 -> T-007179-4/1073-TC-006 | AP10: =Tabela1[[#This Row],[TAG]]&Tabela1[[#This Row],[PEDIDO]]&Tabela1[[#This Row],[PRODUTO]] -> 1073-TC-006P-188BASES ROLETES | AQ10: =Tabela1[[#This Row],[PRODUTO]]&Tabela1[[#This Row],[TAG]] -> BASES ROLETES1073-TC-006 | AR10: =Tabela1[[#This Row],[PEDIDO]]&Tabela1[[#This Row],[PRODUTO]] -> P-188BASES ROLETES | AS10: =IF(AF10="",0,IF(ISTEXT(AF10),H10*VALUE(SUBSTITUTE(AF10,"%",""))/100,H10*AF10))-Tabela1[[#This Row],[PRONTO ACABADO2]] -> 0 | AT10: =IF(AG10="",0,IF(ISTEXT(AG10),H10*VALUE(SUBSTITUTE(AG10,"%",""))/100,H10*AG10))-Tabela1[[#This Row],[PESO EXPEDIDO2]] -> 0 | AU10: =IF(AH10="",0,IF(ISTEXT(AH10),H10*VALUE(SUBSTITUTE(AH10,"%",""))/100,H10*AH10)) -> 51.3 | AV10: =IF(AG10="",0,IF(ISTEXT(AG10),H10*VALUE(SUBSTITUTE(AG10,"%",""))/100,H10*AG10)) -> 51.3
A11: T-007179-4 | C11: 9 | D11: BASE DE RETORNO 7179A | E11: 3401 | F11: 8 | G11: 5.7 | H11: =Tabela1[[#This Row],[PESO UNI]]*Tabela1[[#This Row],[QTE]] -> 51.3 | I11: 0 | J11: 1073-TC-007 | K11: BASES ROLETES | L11: P-188 | M11: 46100 | N11: MDE | Q11: =Tabela1[[#This Row],[QTDE/ Fabricação]]-Tabela1[[#This Row],[QTE]] -> -9 | R11: =IFERROR(H11*((AA11*0.25)+(AC11*0.25)+(AD11*0.225)+(AE11*0.225)+(AF11*0.05)),"") -> 51.3 | S11: =IFERROR(H11*AG11,"") -> 51.3 | T11: =IFERROR(S11-H11,"") -> 0 | U11: =IFERROR(SUMIF('LISTA DE EMBARQUE'!B:B,MICRO!E:E,'LISTA DE EMBARQUE'!G:G),"") -> 9 | V11: =IFERROR(VLOOKUP(Tabela1[[#This Row],[COD.MDE]],'LISTA DE EMBARQUE'!B:L,11,0),"") -> 1 | W11: =IFERROR(VLOOKUP(Tabela1[[#This Row],[COD.MDE]],'LISTA DE EMBARQUE'!B:M,12,0),"") -> 46146 | X11: =IFERROR(Tabela1[[#This Row],[QIANTIDADE EXPEDIDA]]*Tabela1[[#This Row],[PESO UNI]],"") -> 51.3 | Y11: =U11-C11 -> 0 | Z11: =Tabela1[[#This Row],[PESO TOTAL]]-Tabela1[[#This Row],[Peso Expedido]] -> 0 | AA11: 1 | AB11: 1 | AC11: 1 | AD11: 1 | AE11: 1 | AF11: 1 | AG11: 1 | AH11: 1 | AI11: =IF(Z11<=0,"ok","") -> ok | AK11: =Tabela1[[#This Row],[Coluna1]]&Tabela1[[#This Row],[PEDIDO]] -> P-188 | AO11: =A11&"/"&J11 -> T-007179-4/1073-TC-007 | AP11: =Tabela1[[#This Row],[TAG]]&Tabela1[[#This Row],[PEDIDO]]&Tabela1[[#This Row],[PRODUTO]] -> 1073-TC-007P-188BASES ROLETES | AQ11: =Tabela1[[#This Row],[PRODUTO]]&Tabela1[[#This Row],[TAG]] -> BASES ROLETES1073-TC-007 | AR11: =Tabela1[[#This Row],[PEDIDO]]&Tabela1[[#This Row],[PRODUTO]] -> P-188BASES ROLETES | AS11: =IF(AF11="",0,IF(ISTEXT(AF11),H11*VALUE(SUBSTITUTE(AF11,"%",""))/100,H11*AF11))-Tabela1[[#This Row],[PRONTO ACABADO2]] -> 0 | AT11: =IF(AG11="",0,IF(ISTEXT(AG11),H11*VALUE(SUBSTITUTE(AG11,"%",""))/100,H11*AG11))-Tabela1[[#This Row],[PESO EXPEDIDO2]] -> 0 | AU11: =IF(AH11="",0,IF(ISTEXT(AH11),H11*VALUE(SUBSTITUTE(AH11,"%",""))/100,H11*AH11)) -> 51.3 | AV11: =IF(AG11="",0,IF(ISTEXT(AG11),H11*VALUE(SUBSTITUTE(AG11,"%",""))/100,H11*AG11)) -> 51.3
A12: T-007177-1 | C12: 13 | D12: BASE PARA ROLO DE CARGA 7177A | E12: 3402 | F12: 8 | G12: 19.1 | H12: =Tabela1[[#This Row],[PESO UNI]]*Tabela1[[#This Row],[QTE]] -> 248.3 | I12: 1 | J12: 1073-TC-006 | K12: BASES ROLETES | L12: P-188 | M12: 46100 | N12: MDE | Q12: =Tabela1[[#This Row],[QTDE/ Fabricação]]-Tabela1[[#This Row],[QTE]] -> -13 | R12: =IFERROR(H12*((AA12*0.25)+(AC12*0.25)+(AD12*0.225)+(AE12*0.225)+(AF12*0.05)),"") -> 248.3 | S12: =IFERROR(H12*AG12,"") -> 248.3 | T12: =IFERROR(S12-H12,"") -> 0 | U12: =IFERROR(SUMIF('LISTA DE EMBARQUE'!B:B,MICRO!E:E,'LISTA DE EMBARQUE'!G:G),"") -> 11 | V12: =IFERROR(VLOOKUP(Tabela1[[#This Row],[COD.MDE]],'LISTA DE EMBARQUE'!B:L,11,0),"") -> 1 | W12: =IFERROR(VLOOKUP(Tabela1[[#This Row],[COD.MDE]],'LISTA DE EMBARQUE'!B:M,12,0),"") -> 46146 | X12: =IFERROR(Tabela1[[#This Row],[QIANTIDADE EXPEDIDA]]*Tabela1[[#This Row],[PESO UNI]],"") -> 210.1 | Y12: =U12-C12 -> -2 | Z12: =Tabela1[[#This Row],[PESO TOTAL]]-Tabela1[[#This Row],[Peso Expedido]] -> 38.2 | AA12: 1 | AB12: 1 | AC12: 1 | AD12: 1 | AE12: 1 | AF12: 1 | AG12: 1 | AH12: 1 | AI12: =IF(Z12<=0,"ok","") | AK12: =Tabela1[[#This Row],[Coluna1]]&Tabela1[[#This Row],[PEDIDO]] -> P-188 | AO12: =A12&"/"&J12 -> T-007177-1/1073-TC-006 | AP12: =Tabela1[[#This Row],[TAG]]&Tabela1[[#This Row],[PEDIDO]]&Tabela1[[#This Row],[PRODUTO]] -> 1073-TC-006P-188BASES ROLETES | AQ12: =Tabela1[[#This Row],[PRODUTO]]&Tabela1[[#This Row],[TAG]] -> BASES ROLETES1073-TC-006 | AR12: =Tabela1[[#This Row],[PEDIDO]]&Tabela1[[#This Row],[PRODUTO]] -> P-188BASES ROLETES | AS12: =IF(AF12="",0,IF(ISTEXT(AF12),H12*VALUE(SUBSTITUTE(AF12,"%",""))/100,H12*AF12))-Tabela1[[#This Row],[PRONTO ACABADO2]] -> 0 | AT12: =IF(AG12="",0,IF(ISTEXT(AG12),H12*VALUE(SUBSTITUTE(AG12,"%",""))/100,H12*AG12))-Tabela1[[#This Row],[PESO EXPEDIDO2]] -> 0 | AU12: =IF(AH12="",0,IF(ISTEXT(AH12),H12*VALUE(SUBSTITUTE(AH12,"%",""))/100,H12*AH12)) -> 248.3 | AV12: =IF(AG12="",0,IF(ISTEXT(AG12),H12*VALUE(SUBSTITUTE(AG12,"%",""))/100,H12*AG12)) -> 248.3
A13: T-007177-1 | C13: 13 | D13: BASE PARA ROLO DE CARGA 7177A | E13: 3403 | F13: 8 | G13: 19.1 | H13: =Tabela1[[#This Row],[PESO UNI]]*Tabela1[[#This Row],[QTE]] -> 248.3 | I13: 1 | J13: 1073-TC-007 | K13: BASES ROLETES | L13: P-188 | M13: 46100 | N13: MDE | Q13: =Tabela1[[#This Row],[QTDE/ Fabricação]]-Tabela1[[#This Row],[QTE]] -> -13 | R13: =IFERROR(H13*((AA13*0.25)+(AC13*0.25)+(AD13*0.225)+(AE13*0.225)+(AF13*0.05)),"") -> 248.3 | S13: =IFERROR(H13*AG13,"") -> 248.3 | T13: =IFERROR(S13-H13,"") -> 0 | U13: =IFERROR(SUMIF('LISTA DE EMBARQUE'!B:B,MICRO!E:E,'LISTA DE EMBARQUE'!G:G),"") -> 11 | V13: =IFERROR(VLOOKUP(Tabela1[[#This Row],[COD.MDE]],'LISTA DE EMBARQUE'!B:L,11,0),"") -> 1 | W13: =IFERROR(VLOOKUP(Tabela1[[#This Row],[COD.MDE]],'LISTA DE EMBARQUE'!B:M,12,0),"") -> 46146 | X13: =IFERROR(Tabela1[[#This Row],[QIANTIDADE EXPEDIDA]]*Tabela1[[#This Row],[PESO UNI]],"") -> 210.1 | Y13: =U13-C13 -> -2 | Z13: =Tabela1[[#This Row],[PESO TOTAL]]-Tabela1[[#This Row],[Peso Expedido]] -> 38.2 | AA13: 1 | AB13: 1 | AC13: 1 | AD13: 1 | AE13: 1 | AF13: 1 | AG13: 1 | AH13: 1 | AI13: =IF(Z13<=0,"ok","") | AK13: =Tabela1[[#This Row],[Coluna1]]&Tabela1[[#This Row],[PEDIDO]] -> P-188 | AO13: =A13&"/"&J13 -> T-007177-1/1073-TC-007 | AP13: =Tabela1[[#This Row],[TAG]]&Tabela1[[#This Row],[PEDIDO]]&Tabela1[[#This Row],[PRODUTO]] -> 1073-TC-007P-188BASES ROLETES | AQ13: =Tabela1[[#This Row],[PRODUTO]]&Tabela1[[#This Row],[TAG]] -> BASES ROLETES1073-TC-007 | AR13: =Tabela1[[#This Row],[PEDIDO]]&Tabela1[[#This Row],[PRODUTO]] -> P-188BASES ROLETES | AS13: =IF(AF13="",0,IF(ISTEXT(AF13),H13*VALUE(SUBSTITUTE(AF13,"%",""))/100,H13*AF13))-Tabela1[[#This Row],[PRONTO ACABADO2]] -> 0 | AT13: =IF(AG13="",0,IF(ISTEXT(AG13),H13*VALUE(SUBSTITUTE(AG13,"%",""))/100,H13*AG13))-Tabela1[[#This Row],[PESO EXPEDIDO2]] -> 0 | AU13: =IF(AH13="",0,IF(ISTEXT(AH13),H13*VALUE(SUBSTITUTE(AH13,"%",""))/100,H13*AH13)) -> 248.3 | AV13: =IF(AG13="",0,IF(ISTEXT(AG13),H13*VALUE(SUBSTITUTE(AG13,"%",""))/100,H13*AG13)) -> 248.3
A14: T-007175-1 | C14: 2 | D14: BASE P/ ROLO DE TRANSIÇÃO 7175A | E14: 3404 | F14: 8 | G14: 23 | H14: =Tabela1[[#This Row],[PESO UNI]]*Tabela1[[#This Row],[QTE]] -> 46 | I14: 0 | J14: 1073-TC-006 | K14: BASES ROLETES | L14: P-188 | M14: 46100 | N14: MDE | Q14: =Tabela1[[#This Row],[QTDE/ Fabricação]]-Tabela1[[#This Row],[QTE]] -> -2 | R14: =IFERROR(H14*((AA14*0.25)+(AC14*0.25)+(AD14*0.225)+(AE14*0.225)+(AF14*0.05)),"") -> 46 | S14: =IFERROR(H14*AG14,"") -> 46 | T14: =IFERROR(S14-H14,"") -> 0 | U14: =IFERROR(SUMIF('LISTA DE EMBARQUE'!B:B,MICRO!E:E,'LISTA DE EMBARQUE'!G:G),"") -> 2 | V14: =IFERROR(VLOOKUP(Tabela1[[#This Row],[COD.MDE]],'LISTA DE EMBARQUE'!B:L,11,0),"") -> 1 | W14: =IFERROR(VLOOKUP(Tabela1[[#This Row],[COD.MDE]],'LISTA DE EMBARQUE'!B:M,12,0),"") -> 46146 | X14: =IFERROR(Tabela1[[#This Row],[QIANTIDADE EXPEDIDA]]*Tabela1[[#This Row],[PESO UNI]],"") -> 46 | Y14: =U14-C14 -> 0 | Z14: =Tabela1[[#This Row],[PESO TOTAL]]-Tabela1[[#This Row],[Peso Expedido]] -> 0 | AA14: 1 | AB14: 1 | AC14: 1 | AD14: 1 | AE14: 1 | AF14: 1 | AG14: 1 | AH14: 1 | AI14: =IF(Z14<=0,"ok","") -> ok | AK14: =Tabela1[[#This Row],[Coluna1]]&Tabela1[[#This Row],[PEDIDO]] -> P-188 | AO14: =A14&"/"&J14 -> T-007175-1/1073-TC-006 | AP14: =Tabela1[[#This Row],[TAG]]&Tabela1[[#This Row],[PEDIDO]]&Tabela1[[#This Row],[PRODUTO]] -> 1073-TC-006P-188BASES ROLETES | AQ14: =Tabela1[[#This Row],[PRODUTO]]&Tabela1[[#This Row],[TAG]] -> BASES ROLETES1073-TC-006 | AR14: =Tabela1[[#This Row],[PEDIDO]]&Tabela1[[#This Row],[PRODUTO]] -> P-188BASES ROLETES | AS14: =IF(AF14="",0,IF(ISTEXT(AF14),H14*VALUE(SUBSTITUTE(AF14,"%",""))/100,H14*AF14))-Tabela1[[#This Row],[PRONTO ACABADO2]] -> 0 | AT14: =IF(AG14="",0,IF(ISTEXT(AG14),H14*VALUE(SUBSTITUTE(AG14,"%",""))/100,H14*AG14))-Tabela1[[#This Row],[PESO EXPEDIDO2]] -> 0 | AU14: =IF(AH14="",0,IF(ISTEXT(AH14),H14*VALUE(SUBSTITUTE(AH14,"%",""))/100,H14*AH14)) -> 46 | AV14: =IF(AG14="",0,IF(ISTEXT(AG14),H14*VALUE(SUBSTITUTE(AG14,"%",""))/100,H14*AG14)) -> 46
A15: T-007175-1 | C15: 2 | D15: BASE P/ ROLO DE TRANSIÇÃO 7175A | E15: 3405 | F15: 8 | G15: 23 | H15: =Tabela1[[#This Row],[PESO UNI]]*Tabela1[[#This Row],[QTE]] -> 46 | I15: 0 | J15: 1073-TC-007 | K15: BASES ROLETES | L15: P-188 | M15: 46100 | N15: MDE | Q15: =Tabela1[[#This Row],[QTDE/ Fabricação]]-Tabela1[[#This Row],[QTE]] -> -2 | R15: =IFERROR(H15*((AA15*0.25)+(AC15*0.25)+(AD15*0.225)+(AE15*0.225)+(AF15*0.05)),"") -> 46 | S15: =IFERROR(H15*AG15,"") -> 46 | T15: =IFERROR(S15-H15,"") -> 0 | U15: =IFERROR(SUMIF('LISTA DE EMBARQUE'!B:B,MICRO!E:E,'LISTA DE EMBARQUE'!G:G),"") -> 2 | V15: =IFERROR(VLOOKUP(Tabela1[[#This Row],[COD.MDE]],'LISTA DE EMBARQUE'!B:L,11,0),"") -> 1 | W15: =IFERROR(VLOOKUP(Tabela1[[#This Row],[COD.MDE]],'LISTA DE EMBARQUE'!B:M,12,0),"") -> 46146 | X15: =IFERROR(Tabela1[[#This Row],[QIANTIDADE EXPEDIDA]]*Tabela1[[#This Row],[PESO UNI]],"") -> 46 | Y15: =U15-C15 -> 0 | Z15: =Tabela1[[#This Row],[PESO TOTAL]]-Tabela1[[#This Row],[Peso Expedido]] -> 0 | AA15: 1 | AB15: 1 | AC15: 1 | AD15: 1 | AE15: 1 | AF15: 1 | AG15: 1 | AH15: 1 | AI15: =IF(Z15<=0,"ok","") -> ok | AK15: =Tabela1[[#This Row],[Coluna1]]&Tabela1[[#This Row],[PEDIDO]] -> P-188 | AO15: =A15&"/"&J15 -> T-007175-1/1073-TC-007 | AP15: =Tabela1[[#This Row],[TAG]]&Tabela1[[#This Row],[PEDIDO]]&Tabela1[[#This Row],[PRODUTO]] -> 1073-TC-007P-188BASES ROLETES | AQ15: =Tabela1[[#This Row],[PRODUTO]]&Tabela1[[#This Row],[TAG]] -> BASES ROLETES1073-TC-007 | AR15: =Tabela1[[#This Row],[PEDIDO]]&Tabela1[[#This Row],[PRODUTO]] -> P-188BASES ROLETES | AS15: =IF(AF15="",0,IF(ISTEXT(AF15),H15*VALUE(SUBSTITUTE(AF15,"%",""))/100,H15*AF15))-Tabela1[[#This Row],[PRONTO ACABADO2]] -> 0 | AT15: =IF(AG15="",0,IF(ISTEXT(AG15),H15*VALUE(SUBSTITUTE(AG15,"%",""))/100,H15*AG15))-Tabela1[[#This Row],[PESO EXPEDIDO2]] -> 0 | AU15: =IF(AH15="",0,IF(ISTEXT(AH15),H15*VALUE(SUBSTITUTE(AH15,"%",""))/100,H15*AH15)) -> 46 | AV15: =IF(AG15="",0,IF(ISTEXT(AG15),H15*VALUE(SUBSTITUTE(AG15,"%",""))/100,H15*AG15)) -> 46
A16: R-1-4-9218 | C16: 96 | D16: ROLO DE IMPACTO Ø127 / 89 X 380 6305 | E16: 3406 | F16: 7 | G16: 7 | H16: =Tabela1[[#This Row],[PESO UNI]]*Tabela1[[#This Row],[QTE]] -> 672 | I16: 0 | J16: 1073-TC-006 | K16: ROLOS | L16: P-188 | M16: 46100 | N16: MDE | Q16: =Tabela1[[#This Row],[QTDE/ Fabricação]]-Tabela1[[#This Row],[QTE]] -> -96 | R16: =IFERROR(H16*((AA16*0.25)+(AC16*0.25)+(AD16*0.225)+(AE16*0.225)+(AF16*0.05)),"") -> 672 | S16: =IFERROR(H16*AG16,"") -> 672 | T16: =IFERROR(S16-H16,"") -> 0 | U16: =IFERROR(SUMIF('LISTA DE EMBARQUE'!B:B,MICRO!E:E,'LISTA DE EMBARQUE'!G:G),"") -> 99 | V16: =IFERROR(VLOOKUP(Tabela1[[#This Row],[COD.MDE]],'LISTA DE EMBARQUE'!B:L,11,0),"") -> 1 | W16: =IFERROR(VLOOKUP(Tabela1[[#This Row],[COD.MDE]],'LISTA DE EMBARQUE'!B:M,12,0),"") -> 46146 | X16: =IFERROR(Tabela1[[#This Row],[QIANTIDADE EXPEDIDA]]*Tabela1[[#This Row],[PESO UNI]],"") -> 693 | Y16: =U16-C16 -> 3 | Z16: 0 | AA16: 1 | AB16: 1 | AC16: 1 | AD16: 1 | AE16: 1 | AF16: 1 | AG16: 1 | AH16: 1 | AI16: =IF(Z16<=0,"ok","") -> ok | AK16: =Tabela1[[#This Row],[Coluna1]]&Tabela1[[#This Row],[PEDIDO]] -> P-188 | AO16: =A16&"/"&J16 -> R-1-4-9218/1073-TC-006 | AP16: =Tabela1[[#This Row],[TAG]]&Tabela1[[#This Row],[PEDIDO]]&Tabela1[[#This Row],[PRODUTO]] -> 1073-TC-006P-188ROLOS | AQ16: =Tabela1[[#This Row],[PRODUTO]]&Tabela1[[#This Row],[TAG]] -> ROLOS1073-TC-006 | AR16: =Tabela1[[#This Row],[PEDIDO]]&Tabela1[[#This Row],[PRODUTO]] -> P-188ROLOS | AS16: =IF(AF16="",0,IF(ISTEXT(AF16),H16*VALUE(SUBSTITUTE(AF16,"%",""))/100,H16*AF16))-Tabela1[[#This Row],[PRONTO ACABADO2]] -> 0 | AT16: =IF(AG16="",0,IF(ISTEXT(AG16),H16*VALUE(SUBSTITUTE(AG16,"%",""))/100,H16*AG16))-Tabela1[[#This Row],[PESO EXPEDIDO2]] -> 0 | AU16: =IF(AH16="",0,IF(ISTEXT(AH16),H16*VALUE(SUBSTITUTE(AH16,"%",""))/100,H16*AH16)) -> 672 | AV16: =IF(AG16="",0,IF(ISTEXT(AG16),H16*VALUE(SUBSTITUTE(AG16,"%",""))/100,H16*AG16)) -> 672
A17: R-1-4-9218 | C17: 96 | D17: ROLO DE IMPACTO Ø127 / 89 X 380 6305 | E17: 3407 | F17: 7 | G17: 7 | H17: =Tabela1[[#This Row],[PESO UNI]]*Tabela1[[#This Row],[QTE]] -> 672 | I17: 0 | J17: 1073-TC-007 | K17: ROLOS | L17: P-188 | M17: 46100 | N17: MDE | Q17: =Tabela1[[#This Row],[QTDE/ Fabricação]]-Tabela1[[#This Row],[QTE]] -> -96 | R17: =IFERROR(H17*((AA17*0.25)+(AC17*0.25)+(AD17*0.225)+(AE17*0.225)+(AF17*0.05)),"") -> 672 | S17: =IFERROR(H17*AG17,"") -> 672 | T17: =IFERROR(S17-H17,"") -> 0 | U17: =IFERROR(SUMIF('LISTA DE EMBARQUE'!B:B,MICRO!E:E,'LISTA DE EMBARQUE'!G:G),"") -> 99 | V17: =IFERROR(VLOOKUP(Tabela1[[#This Row],[COD.MDE]],'LISTA DE EMBARQUE'!B:L,11,0),"") -> 1 | W17: =IFERROR(VLOOKUP(Tabela1[[#This Row],[COD.MDE]],'LISTA DE EMBARQUE'!B:M,12,0),"") -> 46146 | X17: =IFERROR(Tabela1[[#This Row],[QIANTIDADE EXPEDIDA]]*Tabela1[[#This Row],[PESO UNI]],"") -> 693 | Y17: =U17-C17 -> 3 | Z17: 0 | AA17: 1 | AB17: 1 | AC17: 1 | AD17: 1 | AE17: 1 | AF17: 1 | AG17: 1 | AH17: 1 | AI17: =IF(Z17<=0,"ok","") -> ok | AK17: =Tabela1[[#This Row],[Coluna1]]&Tabela1[[#This Row],[PEDIDO]] -> P-188 | AO17: =A17&"/"&J17 -> R-1-4-9218/1073-TC-007 | AP17: =Tabela1[[#This Row],[TAG]]&Tabela1[[#This Row],[PEDIDO]]&Tabela1[[#This Row],[PRODUTO]] -> 1073-TC-007P-188ROLOS | AQ17: =Tabela1[[#This Row],[PRODUTO]]&Tabela1[[#This Row],[TAG]] -> ROLOS1073-TC-007 | AR17: =Tabela1[[#This Row],[PEDIDO]]&Tabela1[[#This Row],[PRODUTO]] -> P-188ROLOS | AS17: =IF(AF17="",0,IF(ISTEXT(AF17),H17*VALUE(SUBSTITUTE(AF17,"%",""))/100,H17*AF17))-Tabela1[[#This Row],[PRONTO ACABADO2]] -> 0 | AT17: =IF(AG17="",0,IF(ISTEXT(AG17),H17*VALUE(SUBSTITUTE(AG17,"%",""))/100,H17*AG17))-Tabela1[[#This Row],[PESO EXPEDIDO2]] -> 0 | AU17: =IF(AH17="",0,IF(ISTEXT(AH17),H17*VALUE(SUBSTITUTE(AH17,"%",""))/100,H17*AH17)) -> 672 | AV17: =IF(AG17="",0,IF(ISTEXT(AG17),H17*VALUE(SUBSTITUTE(AG17,"%",""))/100,H17*AG17)) -> 672
A18: R-1-4-9211 | C18: 39 | D18: ROLO DE CARGA Ø127 X 380 6305 | E18: 3408 | F18: 7 | G18: 8.5 | H18: =Tabela1[[#This Row],[PESO UNI]]*Tabela1[[#This Row],[QTE]] -> 331.5 | I18: 0 | J18: 1073-TC-006 | K18: ROLOS | L18: P-188 | M18: 46100 | N18: MDE | Q18: =Tabela1[[#This Row],[QTDE/ Fabricação]]-Tabela1[[#This Row],[QTE]] -> -39 | R18: =IFERROR(H18*((AA18*0.25)+(AC18*0.25)+(AD18*0.225)+(AE18*0.225)+(AF18*0.05)),"") -> 331.5 | S18: =IFERROR(H18*AG18,"") -> 331.5 | T18: =IFERROR(S18-H18,"") -> 0 | U18: =IFERROR(SUMIF('LISTA DE EMBARQUE'!B:B,MICRO!E:E,'LISTA DE EMBARQUE'!G:G),"") -> 39 | V18: =IFERROR(VLOOKUP(Tabela1[[#This Row],[COD.MDE]],'LISTA DE EMBARQUE'!B:L,11,0),"") -> 1 | W18: =IFERROR(VLOOKUP(Tabela1[[#This Row],[COD.MDE]],'LISTA DE EMBARQUE'!B:M,12,0),"") -> 46146 | X18: =IFERROR(Tabela1[[#This Row],[QIANTIDADE EXPEDIDA]]*Tabela1[[#This Row],[PESO UNI]],"") -> 331.5 | Y18: =U18-C18 -> 0 | Z18: =Tabela1[[#This Row],[PESO TOTAL]]-Tabela1[[#This Row],[Peso Expedido]] -> 0 | AA18: 1 | AB18: 1 | AC18: 1 | AD18: 1 | AE18: 1 | AF18: 1 | AG18: 1 | AH18: 1 | AI18: =IF(Z18<=0,"ok","") -> ok | AK18: =Tabela1[[#This Row],[Coluna1]]&Tabela1[[#This Row],[PEDIDO]] -> P-188 | AO18: =A18&"/"&J18 -> R-1-4-9211/1073-TC-006 | AP18: =Tabela1[[#This Row],[TAG]]&Tabela1[[#This Row],[PEDIDO]]&Tabela1[[#This Row],[PRODUTO]] -> 1073-TC-006P-188ROLOS | AQ18: =Tabela1[[#This Row],[PRODUTO]]&Tabela1[[#This Row],[TAG]] -> ROLOS1073-TC-006 | AR18: =Tabela1[[#This Row],[PEDIDO]]&Tabela1[[#This Row],[PRODUTO]] -> P-188ROLOS | AS18: =IF(AF18="",0,IF(ISTEXT(AF18),H18*VALUE(SUBSTITUTE(AF18,"%",""))/100,H18*AF18))-Tabela1[[#This Row],[PRONTO ACABADO2]] -> 0 | AT18: =IF(AG18="",0,IF(ISTEXT(AG18),H18*VALUE(SUBSTITUTE(AG18,"%",""))/100,H18*AG18))-Tabela1[[#This Row],[PESO EXPEDIDO2]] -> 0 | AU18: =IF(AH18="",0,IF(ISTEXT(AH18),H18*VALUE(SUBSTITUTE(AH18,"%",""))/100,H18*AH18)) -> 331.5 | AV18: =IF(AG18="",0,IF(ISTEXT(AG18),H18*VALUE(SUBSTITUTE(AG18,"%",""))/100,H18*AG18)) -> 331.5
A19: R-1-4-9211 | C19: 39 | D19: ROLO DE CARGA Ø127 X 380 6305 | E19: 3409 | F19: 7 | G19: 8.5 | H19: =Tabela1[[#This Row],[PESO UNI]]*Tabela1[[#This Row],[QTE]] -> 331.5 | I19: 0 | J19: 1073-TC-007 | K19: ROLOS | L19: P-188 | M19: 46100 | N19: MDE | Q19: =Tabela1[[#This Row],[QTDE/ Fabricação]]-Tabela1[[#This Row],[QTE]] -> -39 | R19: =IFERROR(H19*((AA19*0.25)+(AC19*0.25)+(AD19*0.225)+(AE19*0.225)+(AF19*0.05)),"") -> 331.5 | S19: =IFERROR(H19*AG19,"") -> 331.5 | T19: =IFERROR(S19-H19,"") -> 0 | U19: =IFERROR(SUMIF('LISTA DE EMBARQUE'!B:B,MICRO!E:E,'LISTA DE EMBARQUE'!G:G),"") -> 39 | V19: =IFERROR(VLOOKUP(Tabela1[[#This Row],[COD.MDE]],'LISTA DE EMBARQUE'!B:L,11,0),"") -> 1 | W19: =IFERROR(VLOOKUP(Tabela1[[#This Row],[COD.MDE]],'LISTA DE EMBARQUE'!B:M,12,0),"") -> 46146 | X19: =IFERROR(Tabela1[[#This Row],[QIANTIDADE EXPEDIDA]]*Tabela1[[#This Row],[PESO UNI]],"") -> 331.5 | Y19: =U19-C19 -> 0 | Z19: =Tabela1[[#This Row],[PESO TOTAL]]-Tabela1[[#This Row],[Peso Expedido]] -> 0 | AA19: 1 | AB19: 1 | AC19: 1 | AD19: 1 | AE19: 1 | AF19: 1 | AG19: 1 | AH19: 1 | AI19: =IF(Z19<=0,"ok","") -> ok | AK19: =Tabela1[[#This Row],[Coluna1]]&Tabela1[[#This Row],[PEDIDO]] -> P-188 | AO19: =A19&"/"&J19 -> R-1-4-9211/1073-TC-007 | AP19: =Tabela1[[#This Row],[TAG]]&Tabela1[[#This Row],[PEDIDO]]&Tabela1[[#This Row],[PRODUTO]] -> 1073-TC-007P-188ROLOS | AQ19: =Tabela1[[#This Row],[PRODUTO]]&Tabela1[[#This Row],[TAG]] -> ROLOS1073-TC-007 | AR19: =Tabela1[[#This Row],[PEDIDO]]&Tabela1[[#This Row],[PRODUTO]] -> P-188ROLOS | AS19: =IF(AF19="",0,IF(ISTEXT(AF19),H19*VALUE(SUBSTITUTE(AF19,"%",""))/100,H19*AF19))-Tabela1[[#This Row],[PRONTO ACABADO2]] -> 0 | AT19: =IF(AG19="",0,IF(ISTEXT(AG19),H19*VALUE(SUBSTITUTE(AG19,"%",""))/100,H19*AG19))-Tabela1[[#This Row],[PESO EXPEDIDO2]] -> 0 | AU19: =IF(AH19="",0,IF(ISTEXT(AH19),H19*VALUE(SUBSTITUTE(AH19,"%",""))/100,H19*AH19)) -> 331.5 | AV19: =IF(AG19="",0,IF(ISTEXT(AG19),H19*VALUE(SUBSTITUTE(AG19,"%",""))/100,H19*AG19)) -> 331.5
A20: R-9-4-10210 | C20: 2 | D20: ROLO GUIA Ø56 X 80 | E20: 3410 | F20: 7 | G20: 1 | H20: =Tabela1[[#This Row],[PESO UNI]]*Tabela1[[#This Row],[QTE]] -> 2 | I20: 0 | J20: 1073-TC-006 | K20: ROLOS | L20: P-188 | M20: 46100 | N20: MDE | Q20: =Tabela1[[#This Row],[QTDE/ Fabricação]]-Tabela1[[#This Row],[QTE]] -> -2 | R20: =IFERROR(H20*((AA20*0.25)+(AC20*0.25)+(AD20*0.225)+(AE20*0.225)+(AF20*0.05)),"") -> 2 | S20: =IFERROR(H20*AG20,"") -> 2 | T20: =IFERROR(S20-H20,"") -> 0 | U20: =IFERROR(SUMIF('LISTA DE EMBARQUE'!B:B,MICRO!E:E,'LISTA DE EMBARQUE'!G:G),"") -> 2 | V20: =IFERROR(VLOOKUP(Tabela1[[#This Row],[COD.MDE]],'LISTA DE EMBARQUE'!B:L,11,0),"") -> 1 | W20: =IFERROR(VLOOKUP(Tabela1[[#This Row],[COD.MDE]],'LISTA DE EMBARQUE'!B:M,12,0),"") -> 46146 | X20: =IFERROR(Tabela1[[#This Row],[QIANTIDADE EXPEDIDA]]*Tabela1[[#This Row],[PESO UNI]],"") -> 2 | Y20: =U20-C20 -> 0 | Z20: =Tabela1[[#This Row],[PESO TOTAL]]-Tabela1[[#This Row],[Peso Expedido]] -> 0 | AA20: 1 | AB20: 1 | AC20: 1 | AD20: 1 | AE20: 1 | AF20: 1 | AG20: 1 | AH20: 1 | AI20: =IF(Z20<=0,"ok","") -> ok | AK20: =Tabela1[[#This Row],[Coluna1]]&Tabela1[[#This Row],[PEDIDO]] -> P-188 | AO20: =A20&"/"&J20 -> R-9-4-10210/1073-TC-006 | AP20: =Tabela1[[#This Row],[TAG]]&Tabela1[[#This Row],[PEDIDO]]&Tabela1[[#This Row],[PRODUTO]] -> 1073-TC-006P-188ROLOS | AQ20: =Tabela1[[#This Row],[PRODUTO]]&Tabela1[[#This Row],[TAG]] -> ROLOS1073-TC-006 | AR20: =Tabela1[[#This Row],[PEDIDO]]&Tabela1[[#This Row],[PRODUTO]] -> P-188ROLOS | AS20: =IF(AF20="",0,IF(ISTEXT(AF20),H20*VALUE(SUBSTITUTE(AF20,"%",""))/100,H20*AF20))-Tabela1[[#This Row],[PRONTO ACABADO2]] -> 0 | AT20: =IF(AG20="",0,IF(ISTEXT(AG20),H20*VALUE(SUBSTITUTE(AG20,"%",""))/100,H20*AG20))-Tabela1[[#This Row],[PESO EXPEDIDO2]] -> 0 | AU20: =IF(AH20="",0,IF(ISTEXT(AH20),H20*VALUE(SUBSTITUTE(AH20,"%",""))/100,H20*AH20)) -> 2 | AV20: =IF(AG20="",0,IF(ISTEXT(AG20),H20*VALUE(SUBSTITUTE(AG20,"%",""))/100,H20*AG20)) -> 2
A21: R-9-4-10210 | C21: 2 | D21: ROLO GUIA Ø56 X 80 | E21: 3411 | F21: 7 | G21: 1 | H21: =Tabela1[[#This Row],[PESO UNI]]*Tabela1[[#This Row],[QTE]] -> 2 | I21: 0 | J21: 1073-TC-007 | K21: ROLOS | L21: P-188 | M21: 46100 | N21: MDE | Q21: =Tabela1[[#This Row],[QTDE/ Fabricação]]-Tabela1[[#This Row],[QTE]] -> -2 | R21: =IFERROR(H21*((AA21*0.25)+(AC21*0.25)+(AD21*0.225)+(AE21*0.225)+(AF21*0.05)),"") -> 2 | S21: =IFERROR(H21*AG21,"") -> 2 | T21: =IFERROR(S21-H21,"") -> 0 | U21: =IFERROR(SUMIF('LISTA DE EMBARQUE'!B:B,MICRO!E:E,'LISTA DE EMBARQUE'!G:G),"") -> 2 | V21: =IFERROR(VLOOKUP(Tabela1[[#This Row],[COD.MDE]],'LISTA DE EMBARQUE'!B:L,11,0),"") -> 1 | W21: =IFERROR(VLOOKUP(Tabela1[[#This Row],[COD.MDE]],'LISTA DE EMBARQUE'!B:M,12,0),"") -> 46146 | X21: =IFERROR(Tabela1[[#This Row],[QIANTIDADE EXPEDIDA]]*Tabela1[[#This Row],[PESO UNI]],"") -> 2 | Y21: =U21-C21 -> 0 | Z21: =Tabela1[[#This Row],[PESO TOTAL]]-Tabela1[[#This Row],[Peso Expedido]] -> 0 | AA21: 1 | AB21: 1 | AC21: 1 | AD21: 1 | AE21: 1 | AF21: 1 | AG21: 1 | AH21: 1 | AI21: =IF(Z21<=0,"ok","") -> ok | AK21: =Tabela1[[#This Row],[Coluna1]]&Tabela1[[#This Row],[PEDIDO]] -> P-188 | AO21: =A21&"/"&J21 -> R-9-4-10210/1073-TC-007 | AP21: =Tabela1[[#This Row],[TAG]]&Tabela1[[#This Row],[PEDIDO]]&Tabela1[[#This Row],[PRODUTO]] -> 1073-TC-007P-188ROLOS | AQ21: =Tabela1[[#This Row],[PRODUTO]]&Tabela1[[#This Row],[TAG]] -> ROLOS1073-TC-007 | AR21: =Tabela1[[#This Row],[PEDIDO]]&Tabela1[[#This Row],[PRODUTO]] -> P-188ROLOS | AS21: =IF(AF21="",0,IF(ISTEXT(AF21),H21*VALUE(SUBSTITUTE(AF21,"%",""))/100,H21*AF21))-Tabela1[[#This Row],[PRONTO ACABADO2]] -> 0 | AT21: =IF(AG21="",0,IF(ISTEXT(AG21),H21*VALUE(SUBSTITUTE(AG21,"%",""))/100,H21*AG21))-Tabela1[[#This Row],[PESO EXPEDIDO2]] -> 0 | AU21: =IF(AH21="",0,IF(ISTEXT(AH21),H21*VALUE(SUBSTITUTE(AH21,"%",""))/100,H21*AH21)) -> 2 | AV21: =IF(AG21="",0,IF(ISTEXT(AG21),H21*VALUE(SUBSTITUTE(AG21,"%",""))/100,H21*AG21)) -> 2
A22: R-1-4-10944 | C22: 4 | D22: ROLO DE PROTEÇÃO Ø89 X 150 6204 | E22: 3412 | F22: 7 | G22: 2.5 | H22: =Tabela1[[#This Row],[PESO UNI]]*Tabela1[[#This Row],[QTE]] -> 10 | I22: 0 | J22: 1073-TC-006 | K22: ROLOS | L22: P-188 | M22: 46100 | N22: MDE | Q22: =Tabela1[[#This Row],[QTDE/ Fabricação]]-Tabela1[[#This Row],[QTE]] -> -4 | R22: =IFERROR(H22*((AA22*0.25)+(AC22*0.25)+(AD22*0.225)+(AE22*0.225)+(AF22*0.05)),"") -> 10 | S22: =IFERROR(H22*AG22,"") -> 10 | T22: =IFERROR(S22-H22,"") -> 0 | U22: =IFERROR(SUMIF('LISTA DE EMBARQUE'!B:B,MICRO!E:E,'LISTA DE EMBARQUE'!G:G),"") -> 4 | V22: =IFERROR(VLOOKUP(Tabela1[[#This Row],[COD.MDE]],'LISTA DE EMBARQUE'!B:L,11,0),"") -> 1 | W22: =IFERROR(VLOOKUP(Tabela1[[#This Row],[COD.MDE]],'LISTA DE EMBARQUE'!B:M,12,0),"") -> 46146 | X22: =IFERROR(Tabela1[[#This Row],[QIANTIDADE EXPEDIDA]]*Tabela1[[#This Row],[PESO UNI]],"") -> 10 | Y22: =U22-C22 -> 0 | Z22: =Tabela1[[#This Row],[PESO TOTAL]]-Tabela1[[#This Row],[Peso Expedido]] -> 0 | AA22: 1 | AB22: 1 | AC22: 1 | AD22: 1 | AE22: 1 | AF22: 1 | AG22: 1 | AH22: 1 | AI22: =IF(Z22<=0,"ok","") -> ok | AK22: =Tabela1[[#This Row],[Coluna1]]&Tabela1[[#This Row],[PEDIDO]] -> P-188 | AO22: =A22&"/"&J22 -> R-1-4-10944/1073-TC-006 | AP22: =Tabela1[[#This Row],[TAG]]&Tabela1[[#This Row],[PEDIDO]]&Tabela1[[#This Row],[PRODUTO]] -> 1073-TC-006P-188ROLOS | AQ22: =Tabela1[[#This Row],[PRODUTO]]&Tabela1[[#This Row],[TAG]] -> ROLOS1073-TC-006 | AR22: =Tabela1[[#This Row],[PEDIDO]]&Tabela1[[#This Row],[PRODUTO]] -> P-188ROLOS | AS22: =IF(AF22="",0,IF(ISTEXT(AF22),H22*VALUE(SUBSTITUTE(AF22,"%",""))/100,H22*AF22))-Tabela1[[#This Row],[PRONTO ACABADO2]] -> 0 | AT22: =IF(AG22="",0,IF(ISTEXT(AG22),H22*VALUE(SUBSTITUTE(AG22,"%",""))/100,H22*AG22))-Tabela1[[#This Row],[PESO EXPEDIDO2]] -> 0 | AU22: =IF(AH22="",0,IF(ISTEXT(AH22),H22*VALUE(SUBSTITUTE(AH22,"%",""))/100,H22*AH22)) -> 10 | AV22: =IF(AG22="",0,IF(ISTEXT(AG22),H22*VALUE(SUBSTITUTE(AG22,"%",""))/100,H22*AG22)) -> 10
A23: R-1-4-10944 | C23: 4 | D23: ROLO DE PROTEÇÃO Ø89 X 150 6204 | E23: 3413 | F23: 7 | G23: 2.5 | H23: =Tabela1[[#This Row],[PESO UNI]]*Tabela1[[#This Row],[QTE]] -> 10 | I23: 0 | J23: 1073-TC-007 | K23: ROLOS | L23: P-188 | M23: 46100 | N23: MDE | Q23: =Tabela1[[#This Row],[QTDE/ Fabricação]]-Tabela1[[#This Row],[QTE]] -> -4 | R23: =IFERROR(H23*((AA23*0.25)+(AC23*0.25)+(AD23*0.225)+(AE23*0.225)+(AF23*0.05)),"") -> 10 | S23: =IFERROR(H23*AG23,"") -> 10 | T23: =IFERROR(S23-H23,"") -> 0 | U23: =IFERROR(SUMIF('LISTA DE EMBARQUE'!B:B,MICRO!E:E,'LISTA DE EMBARQUE'!G:G),"") -> 4 | V23: =IFERROR(VLOOKUP(Tabela1[[#This Row],[COD.MDE]],'LISTA DE EMBARQUE'!B:L,11,0),"") -> 1 | W23: =IFERROR(VLOOKUP(Tabela1[[#This Row],[COD.MDE]],'LISTA DE EMBARQUE'!B:M,12,0),"") -> 46146 | X23: =IFERROR(Tabela1[[#This Row],[QIANTIDADE EXPEDIDA]]*Tabela1[[#This Row],[PESO UNI]],"") -> 10 | Y23: =U23-C23 -> 0 | Z23: =Tabela1[[#This Row],[PESO TOTAL]]-Tabela1[[#This Row],[Peso Expedido]] -> 0 | AA23: 1 | AB23: 1 | AC23: 1 | AD23: 1 | AE23: 1 | AF23: 1 | AG23: 1 | AH23: 1 | AI23: =IF(Z23<=0,"ok","") -> ok | AK23: =Tabela1[[#This Row],[Coluna1]]&Tabela1[[#This Row],[PEDIDO]] -> P-188 | AO23: =A23&"/"&J23 -> R-1-4-10944/1073-TC-007 | AP23: =Tabela1[[#This Row],[TAG]]&Tabela1[[#This Row],[PEDIDO]]&Tabela1[[#This Row],[PRODUTO]] -> 1073-TC-007P-188ROLOS | AQ23: =Tabela1[[#This Row],[PRODUTO]]&Tabela1[[#This Row],[TAG]] -> ROLOS1073-TC-007 | AR23: =Tabela1[[#This Row],[PEDIDO]]&Tabela1[[#This Row],[PRODUTO]] -> P-188ROLOS | AS23: =IF(AF23="",0,IF(ISTEXT(AF23),H23*VALUE(SUBSTITUTE(AF23,"%",""))/100,H23*AF23))-Tabela1[[#This Row],[PRONTO ACABADO2]] -> 0 | AT23: =IF(AG23="",0,IF(ISTEXT(AG23),H23*VALUE(SUBSTITUTE(AG23,"%",""))/100,H23*AG23))-Tabela1[[#This Row],[PESO EXPEDIDO2]] -> 0 | AU23: =IF(AH23="",0,IF(ISTEXT(AH23),H23*VALUE(SUBSTITUTE(AH23,"%",""))/100,H23*AH23)) -> 10 | AV23: =IF(AG23="",0,IF(ISTEXT(AG23),H23*VALUE(SUBSTITUTE(AG23,"%",""))/100,H23*AG23)) -> 10
A24: R-3-4-10912 | C24: 14 | D24: ROLO DE BALANÇA Ø127 X 380 6305 | E24: 3414 | F24: 7 | G24: 8.5 | H24: =Tabela1[[#This Row],[PESO UNI]]*Tabela1[[#This Row],[QTE]] -> 119 | I24: 0 | J24: 1073-TC-006 | K24: ROLOS | L24: P-188 | M24: 46100 | N24: MDE | Q24: =Tabela1[[#This Row],[QTDE/ Fabricação]]-Tabela1[[#This Row],[QTE]] -> -14 | R24: =IFERROR(H24*((AA24*0.25)+(AC24*0.25)+(AD24*0.225)+(AE24*0.225)+(AF24*0.05)),"") -> 119 | S24: =IFERROR(H24*AG24,"") -> 119 | T24: =IFERROR(S24-H24,"") -> 0 | U24: =IFERROR(SUMIF('LISTA DE EMBARQUE'!B:B,MICRO!E:E,'LISTA DE EMBARQUE'!G:G),"") -> 14 | V24: =IFERROR(VLOOKUP(Tabela1[[#This Row],[COD.MDE]],'LISTA DE EMBARQUE'!B:L,11,0),"") -> 4 | W24: =IFERROR(VLOOKUP(Tabela1[[#This Row],[COD.MDE]],'LISTA DE EMBARQUE'!B:M,12,0),"") -> 46174 | X24: =IFERROR(Tabela1[[#This Row],[QIANTIDADE EXPEDIDA]]*Tabela1[[#This Row],[PESO UNI]],"") -> 119 | Y24: =U24-C24 -> 0 | Z24: =Tabela1[[#This Row],[PESO TOTAL]]-Tabela1[[#This Row],[Peso Expedido]] -> 0 | AA24: 1 | AB24: 1 | AC24: 1 | AD24: 1 | AE24: 1 | AF24: 1 | AG24: 1 | AH24: 1 | AI24: ok | AK24: =Tabela1[[#This Row],[Coluna1]]&Tabela1[[#This Row],[PEDIDO]] -> P-188 | AO24: =A24&"/"&J24 -> R-3-4-10912/1073-TC-006 | AP24: =Tabela1[[#This Row],[TAG]]&Tabela1[[#This Row],[PEDIDO]]&Tabela1[[#This Row],[PRODUTO]] -> 1073-TC-006P-188ROLOS | AQ24: =Tabela1[[#This Row],[PRODUTO]]&Tabela1[[#This Row],[TAG]] -> ROLOS1073-TC-006 | AR24: =Tabela1[[#This Row],[PEDIDO]]&Tabela1[[#This Row],[PRODUTO]] -> P-188ROLOS | AS24: =IF(AF24="",0,IF(ISTEXT(AF24),H24*VALUE(SUBSTITUTE(AF24,"%",""))/100,H24*AF24))-Tabela1[[#This Row],[PRONTO ACABADO2]] -> 0 | AT24: =IF(AG24="",0,IF(ISTEXT(AG24),H24*VALUE(SUBSTITUTE(AG24,"%",""))/100,H24*AG24))-Tabela1[[#This Row],[PESO EXPEDIDO2]] -> 0 | AU24: =IF(AH24="",0,IF(ISTEXT(AH24),H24*VALUE(SUBSTITUTE(AH24,"%",""))/100,H24*AH24)) -> 119 | AV24: =IF(AG24="",0,IF(ISTEXT(AG24),H24*VALUE(SUBSTITUTE(AG24,"%",""))/100,H24*AG24)) -> 119
A25: R-3-4-10912 | C25: 14 | D25: ROLO DE BALANÇA Ø127 X 380 6305 | E25: 3415 | F25: 7 | G25: 8.5 | H25: =Tabela1[[#This Row],[PESO UNI]]*Tabela1[[#This Row],[QTE]] -> 119 | I25: 0 | J25: 1073-TC-007 | K25: ROLOS | L25: P-188 | M25: 46100 | N25: MDE | Q25: =Tabela1[[#This Row],[QTDE/ Fabricação]]-Tabela1[[#This Row],[QTE]] -> -14 | R25: =IFERROR(H25*((AA25*0.25)+(AC25*0.25)+(AD25*0.225)+(AE25*0.225)+(AF25*0.05)),"") -> 119 | S25: =IFERROR(H25*AG25,"") -> 119 | T25: =IFERROR(S25-H25,"") -> 0 | U25: =IFERROR(SUMIF('LISTA DE EMBARQUE'!B:B,MICRO!E:E,'LISTA DE EMBARQUE'!G:G),"") -> 28 | V25: =IFERROR(VLOOKUP(Tabela1[[#This Row],[COD.MDE]],'LISTA DE EMBARQUE'!B:L,11,0),"") -> 4 | W25: =IFERROR(VLOOKUP(Tabela1[[#This Row],[COD.MDE]],'LISTA DE EMBARQUE'!B:M,12,0),"") -> 46174 | X25: =IFERROR(Tabela1[[#This Row],[QIANTIDADE EXPEDIDA]]*Tabela1[[#This Row],[PESO UNI]],"") -> 238 | Y25: =U25-C25 -> 14 | Z25: 0 | AA25: 1 | AB25: 1 | AC25: 1 | AD25: 1 | AE25: 1 | AF25: 1 | AG25: 1 | AH25: 1 | AI25: ok | AK25: =Tabela1[[#This Row],[Coluna1]]&Tabela1[[#This Row],[PEDIDO]] -> P-188 | AO25: =A25&"/"&J25 -> R-3-4-10912/1073-TC-007 | AP25: =Tabela1[[#This Row],[TAG]]&Tabela1[[#This Row],[PEDIDO]]&Tabela1[[#This Row],[PRODUTO]] -> 1073-TC-007P-188ROLOS | AQ25: =Tabela1[[#This Row],[PRODUTO]]&Tabela1[[#This Row],[TAG]] -> ROLOS1073-TC-007 | AR25: =Tabela1[[#This Row],[PEDIDO]]&Tabela1[[#This Row],[PRODUTO]] -> P-188ROLOS | AS25: =IF(AF25="",0,IF(ISTEXT(AF25),H25*VALUE(SUBSTITUTE(AF25,"%",""))/100,H25*AF25))-Tabela1[[#This Row],[PRONTO ACABADO2]] -> 0 | AT25: =IF(AG25="",0,IF(ISTEXT(AG25),H25*VALUE(SUBSTITUTE(AG25,"%",""))/100,H25*AG25))-Tabela1[[#This Row],[PESO EXPEDIDO2]] -> 0 | AU25: =IF(AH25="",0,IF(ISTEXT(AH25),H25*VALUE(SUBSTITUTE(AH25,"%",""))/100,H25*AH25)) -> 119 | AV25: =IF(AG25="",0,IF(ISTEXT(AG25),H25*VALUE(SUBSTITUTE(AG25,"%",""))/100,H25*AG25)) -> 119
A26: R-3-4-7843 | C26: 10 | D26: ROLO DE RETORNO Ø127 / 89 X 1150 - 6305 | E26: 3416 | F26: 7 | G26: 19.8 | H26: =Tabela1[[#This Row],[PESO UNI]]*Tabela1[[#This Row],[QTE]] -> 198 | I26: 0 | J26: 1073-TC-006 | K26: ROLOS | L26: P-188 | M26: 46100 | N26: MDE | Q26: =Tabela1[[#This Row],[QTDE/ Fabricação]]-Tabela1[[#This Row],[QTE]] -> -10 | R26: =IFERROR(H26*((AA26*0.25)+(AC26*0.25)+(AD26*0.225)+(AE26*0.225)+(AF26*0.05)),"") -> 198 | S26: =IFERROR(H26*AG26,"") -> 198 | T26: =IFERROR(S26-H26,"") -> 0 | U26: =IFERROR(SUMIF('LISTA DE EMBARQUE'!B:B,MICRO!E:E,'LISTA DE EMBARQUE'!G:G),"") -> 10 | V26: =IFERROR(VLOOKUP(Tabela1[[#This Row],[COD.MDE]],'LISTA DE EMBARQUE'!B:L,11,0),"") -> 1 | W26: =IFERROR(VLOOKUP(Tabela1[[#This Row],[COD.MDE]],'LISTA DE EMBARQUE'!B:M,12,0),"") -> 46146 | X26: =IFERROR(Tabela1[[#This Row],[QIANTIDADE EXPEDIDA]]*Tabela1[[#This Row],[PESO UNI]],"") -> 198 | Y26: =U26-C26 -> 0 | Z26: =Tabela1[[#This Row],[PESO TOTAL]]-Tabela1[[#This Row],[Peso Expedido]] -> 0 | AA26: 1 | AB26: 1 | AC26: 1 | AD26: 1 | AE26: 1 | AF26: 1 | AG26: 1 | AH26: 1 | AI26: =IF(Z26<=0,"ok","") -> ok | AK26: =Tabela1[[#This Row],[Coluna1]]&Tabela1[[#This Row],[PEDIDO]] -> P-188 | AO26: =A26&"/"&J26 -> R-3-4-7843/1073-TC-006 | AP26: =Tabela1[[#This Row],[TAG]]&Tabela1[[#This Row],[PEDIDO]]&Tabela1[[#This Row],[PRODUTO]] -> 1073-TC-006P-188ROLOS | AQ26: =Tabela1[[#This Row],[PRODUTO]]&Tabela1[[#This Row],[TAG]] -> ROLOS1073-TC-006 | AR26: =Tabela1[[#This Row],[PEDIDO]]&Tabela1[[#This Row],[PRODUTO]] -> P-188ROLOS | AS26: =IF(AF26="",0,IF(ISTEXT(AF26),H26*VALUE(SUBSTITUTE(AF26,"%",""))/100,H26*AF26))-Tabela1[[#This Row],[PRONTO ACABADO2]] -> 0 | AT26: =IF(AG26="",0,IF(ISTEXT(AG26),H26*VALUE(SUBSTITUTE(AG26,"%",""))/100,H26*AG26))-Tabela1[[#This Row],[PESO EXPEDIDO2]] -> 0 | AU26: =IF(AH26="",0,IF(ISTEXT(AH26),H26*VALUE(SUBSTITUTE(AH26,"%",""))/100,H26*AH26)) -> 198 | AV26: =IF(AG26="",0,IF(ISTEXT(AG26),H26*VALUE(SUBSTITUTE(AG26,"%",""))/100,H26*AG26)) -> 198
A27: R-3-4-7843 | C27: 10 | D27: ROLO DE RETORNO Ø127 / 89 X 1150 - 6305 | E27: 3417 | F27: 7 | G27: 19.8 | H27: =Tabela1[[#This Row],[PESO UNI]]*Tabela1[[#This Row],[QTE]] -> 198 | I27: 0 | J27: 1073-TC-007 | K27: ROLOS | L27: P-188 | M27: 46100 | N27: MDE | Q27: =Tabela1[[#This Row],[QTDE/ Fabricação]]-Tabela1[[#This Row],[QTE]] -> -10 | R27: =IFERROR(H27*((AA27*0.25)+(AC27*0.25)+(AD27*0.225)+(AE27*0.225)+(AF27*0.05)),"") -> 198 | S27: =IFERROR(H27*AG27,"") -> 198 | T27: =IFERROR(S27-H27,"") -> 0 | U27: =IFERROR(SUMIF('LISTA DE EMBARQUE'!B:B,MICRO!E:E,'LISTA DE EMBARQUE'!G:G),"") -> 12 | V27: =IFERROR(VLOOKUP(Tabela1[[#This Row],[COD.MDE]],'LISTA DE EMBARQUE'!B:L,11,0),"") -> 1 | W27: =IFERROR(VLOOKUP(Tabela1[[#This Row],[COD.MDE]],'LISTA DE EMBARQUE'!B:M,12,0),"") -> 46146 | X27: =IFERROR(Tabela1[[#This Row],[QIANTIDADE EXPEDIDA]]*Tabela1[[#This Row],[PESO UNI]],"") -> 237.6 | Y27: =U27-C27 -> 2 | Z27: 0 | AA27: 1 | AB27: 1 | AC27: 1 | AD27: 1 | AE27: 1 | AF27: 1 | AG27: 1 | AH27: 1 | AI27: =IF(Z27<=0,"ok","") -> ok | AK27: =Tabela1[[#This Row],[Coluna1]]&Tabela1[[#This Row],[PEDIDO]] -> P-188 | AO27: =A27&"/"&J27 -> R-3-4-7843/1073-TC-007 | AP27: =Tabela1[[#This Row],[TAG]]&Tabela1[[#This Row],[PEDIDO]]&Tabela1[[#This Row],[PRODUTO]] -> 1073-TC-007P-188ROLOS | AQ27: =Tabela1[[#This Row],[PRODUTO]]&Tabela1[[#This Row],[TAG]] -> ROLOS1073-TC-007 | AR27: =Tabela1[[#This Row],[PEDIDO]]&Tabela1[[#This Row],[PRODUTO]] -> P-188ROLOS | AS27: =IF(AF27="",0,IF(ISTEXT(AF27),H27*VALUE(SUBSTITUTE(AF27,"%",""))/100,H27*AF27))-Tabela1[[#This Row],[PRONTO ACABADO2]] -> 0 | AT27: =IF(AG27="",0,IF(ISTEXT(AG27),H27*VALUE(SUBSTITUTE(AG27,"%",""))/100,H27*AG27))-Tabela1[[#This Row],[PESO EXPEDIDO2]] -> 0 | AU27: =IF(AH27="",0,IF(ISTEXT(AH27),H27*VALUE(SUBSTITUTE(AH27,"%",""))/100,H27*AH27)) -> 198 | AV27: =IF(AG27="",0,IF(ISTEXT(AG27),H27*VALUE(SUBSTITUTE(AG27,"%",""))/100,H27*AG27)) -> 198
A28: A-010003-1 | C28: 10 | D28: SAPATA METÁLICA | E28: 3720 | F28: 1 | G28: 97.6 | H28: =Tabela1[[#This Row],[PESO UNI]]*Tabela1[[#This Row],[QTE]] -> 976 | I28: 3 | J28: P200 | K28: ESTRUTURA | L28: P-200 | M28: 46155 | N28: MDE | Q28: =Tabela1[[#This Row],[QTDE/ Fabricação]]-Tabela1[[#This Row],[QTE]] -> -10 | R28: =IFERROR(H28*((AA28*0.25)+(AC28*0.25)+(AD28*0.225)+(AE28*0.225)+(AF28*0.05)),"") -> 976 | S28: =IFERROR(H28*AG28,"") -> 976 | T28: =IFERROR(S28-H28,"") -> 0 | U28: =IFERROR(SUMIF('LISTA DE EMBARQUE'!B:B,MICRO!E:E,'LISTA DE EMBARQUE'!G:G),"") -> 10 | V28: =IFERROR(VLOOKUP(Tabela1[[#This Row],[COD.MDE]],'LISTA DE EMBARQUE'!B:L,11,0),"") -> 1 | W28: =IFERROR(VLOOKUP(Tabela1[[#This Row],[COD.MDE]],'LISTA DE EMBARQUE'!B:M,12,0),"") -> 46209 | X28: =IFERROR(Tabela1[[#This Row],[QIANTIDADE EXPEDIDA]]*Tabela1[[#This Row],[PESO UNI]],"") -> 976 | Y28: =U28-C28 -> 0 | Z28: =Tabela1[[#This Row],[PESO TOTAL]]-Tabela1[[#This Row],[Peso Expedido]] -> 0 | AA28: 1 | AC28: 1 | AD28: 1 | AE28: 1 | AF28: 1 | AG28: 1 | AH28: 1 | AI28: =IF(Z28<=0,"ok","") -> ok | AK28: =Tabela1[[#This Row],[Coluna1]]&Tabela1[[#This Row],[PEDIDO]] -> P-200 | AO28: =A28&"/"&J28 -> A-010003-1/P200 | AP28: =Tabela1[[#This Row],[TAG]]&Tabela1[[#This Row],[PEDIDO]]&Tabela1[[#This Row],[PRODUTO]] -> P200P-200ESTRUTURA | AQ28: =Tabela1[[#This Row],[PRODUTO]]&Tabela1[[#This Row],[TAG]] -> ESTRUTURAP200 | AR28: =Tabela1[[#This Row],[PEDIDO]]&Tabela1[[#This Row],[PRODUTO]] -> P-200ESTRUTURA | AS28: =IF(AF28="",0,IF(ISTEXT(AF28),H28*VALUE(SUBSTITUTE(AF28,"%",""))/100,H28*AF28))-Tabela1[[#This Row],[PRONTO ACABADO2]] -> 0 | AT28: =IF(AG28="",0,IF(ISTEXT(AG28),H28*VALUE(SUBSTITUTE(AG28,"%",""))/100,H28*AG28))-Tabela1[[#This Row],[PESO EXPEDIDO2]] -> 0 | AU28: =IF(AH28="",0,IF(ISTEXT(AH28),H28*VALUE(SUBSTITUTE(AH28,"%",""))/100,H28*AH28)) -> 976 | AV28: =IF(AG28="",0,IF(ISTEXT(AG28),H28*VALUE(SUBSTITUTE(AG28,"%",""))/100,H28*AG28)) -> 976
A29: T-009362-1 | C29: 1 | D29: TAMBOR DE DESVIO Ø457 x 1016 | E29: 3721 | F29: 1 | G29: 213.7 | H29: =Tabela1[[#This Row],[PESO UNI]]*Tabela1[[#This Row],[QTE]] -> 213.7 | I29: A | J29: P201 | K29: TAMBOR | L29: P-201 | M29: 46155 | N29: MDE | Q29: =Tabela1[[#This Row],[QTDE/ Fabricação]]-Tabela1[[#This Row],[QTE]] -> -1 | R29: =IFERROR(H29*((AA29*0.25)+(AC29*0.25)+(AD29*0.225)+(AE29*0.225)+(AF29*0.05)),"") -> 213.7 | S29: =IFERROR(H29*AG29,"") -> 213.7 | T29: =IFERROR(S29-H29,"") -> 0 | U29: 1 | V29: 1 | W29: =IFERROR(VLOOKUP(Tabela1[[#This Row],[COD.MDE]],'LISTA DE EMBARQUE'!B:M,12,0),"") | X29: =IFERROR(Tabela1[[#This Row],[QIANTIDADE EXPEDIDA]]*Tabela1[[#This Row],[PESO UNI]],"") -> 213.7 | Y29: =U29-C29 -> 0 | Z29: =Tabela1[[#This Row],[PESO TOTAL]]-Tabela1[[#This Row],[Peso Expedido]] -> 0 | AA29: 1 | AC29: 1 | AD29: 1 | AE29: 1 | AF29: 1 | AG29: 1 | AH29: 1 | AI29: ok | AK29: =Tabela1[[#This Row],[Coluna1]]&Tabela1[[#This Row],[PEDIDO]] -> P-201 | AO29: =A29&"/"&J29 -> T-009362-1/P201 | AP29: =Tabela1[[#This Row],[TAG]]&Tabela1[[#This Row],[PEDIDO]]&Tabela1[[#This Row],[PRODUTO]] -> P201P-201TAMBOR | AQ29: =Tabela1[[#This Row],[PRODUTO]]&Tabela1[[#This Row],[TAG]] -> TAMBORP201 | AR29: =Tabela1[[#This Row],[PEDIDO]]&Tabela1[[#This Row],[PRODUTO]] -> P-201TAMBOR | AS29: =IF(AF29="",0,IF(ISTEXT(AF29),H29*VALUE(SUBSTITUTE(AF29,"%",""))/100,H29*AF29))-Tabela1[[#This Row],[PRONTO ACABADO2]] -> 0 | AT29: =IF(AG29="",0,IF(ISTEXT(AG29),H29*VALUE(SUBSTITUTE(AG29,"%",""))/100,H29*AG29))-Tabela1[[#This Row],[PESO EXPEDIDO2]] -> 0 | AU29: =IF(AH29="",0,IF(ISTEXT(AH29),H29*VALUE(SUBSTITUTE(AH29,"%",""))/100,H29*AH29)) -> 213.7 | AV29: =IF(AG29="",0,IF(ISTEXT(AG29),H29*VALUE(SUBSTITUTE(AG29,"%",""))/100,H29*AG29)) -> 213.7
A30: R-1-4-10944 | C30: 4 | D30: ROLO PROTEÇÃO Ø89 x 150 6204 | E30: 3722 | F30: 1 | G30: 2.5 | H30: =Tabela1[[#This Row],[PESO UNI]]*Tabela1[[#This Row],[QTE]] -> 10 | I30: 0 | J30: P202 | K30: ROLOS | L30: P-202 | M30: 46162 | N30: MDE | Q30: =Tabela1[[#This Row],[QTDE/ Fabricação]]-Tabela1[[#This Row],[QTE]] -> -4 | R30: =IFERROR(H30*((AA30*0.25)+(AC30*0.25)+(AD30*0.225)+(AE30*0.225)+(AF30*0.05)),"") -> 10 | S30: =IFERROR(H30*AG30,"") -> 10 | T30: =IFERROR(S30-H30,"") -> 0 | U30: =IFERROR(SUMIF('LISTA DE EMBARQUE'!B:B,MICRO!E:E,'LISTA DE EMBARQUE'!G:G),"") -> 4 | V30: =IFERROR(VLOOKUP(Tabela1[[#This Row],[COD.MDE]],'LISTA DE EMBARQUE'!B:L,11,0),"") -> 1 | W30: =IFERROR(VLOOKUP(Tabela1[[#This Row],[COD.MDE]],'LISTA DE EMBARQUE'!B:M,12,0),"") -> 46049 | X30: =IFERROR(Tabela1[[#This Row],[QIANTIDADE EXPEDIDA]]*Tabela1[[#This Row],[PESO UNI]],"") -> 10 | Y30: =U30-C30 -> 0 | Z30: =Tabela1[[#This Row],[PESO TOTAL]]-Tabela1[[#This Row],[Peso Expedido]] -> 0 | AA30: 1 | AB30: 1 | AC30: 1 | AD30: 1 | AE30: 1 | AF30: 1 | AG30: 1 | AH30: 1 | AI30: =IF(Z30<=0,"ok","") -> ok | AK30: =Tabela1[[#This Row],[Coluna1]]&Tabela1[[#This Row],[PEDIDO]] -> P-202 | AO30: =A30&"/"&J30 -> R-1-4-10944/P202 | AP30: =Tabela1[[#This Row],[TAG]]&Tabela1[[#This Row],[PEDIDO]]&Tabela1[[#This Row],[PRODUTO]] -> P202P-202ROLOS | AQ30: =Tabela1[[#This Row],[PRODUTO]]&Tabela1[[#This Row],[TAG]] -> ROLOSP202 | AR30: =Tabela1[[#This Row],[PEDIDO]]&Tabela1[[#This Row],[PRODUTO]] -> P-202ROLOS | AS30: =IF(AF30="",0,IF(ISTEXT(AF30),H30*VALUE(SUBSTITUTE(AF30,"%",""))/100,H30*AF30))-Tabela1[[#This Row],[PRONTO ACABADO2]] -> 0 | AT30: =IF(AG30="",0,IF(ISTEXT(AG30),H30*VALUE(SUBSTITUTE(AG30,"%",""))/100,H30*AG30))-Tabela1[[#This Row],[PESO EXPEDIDO2]] -> 0 | AU30: =IF(AH30="",0,IF(ISTEXT(AH30),H30*VALUE(SUBSTITUTE(AH30,"%",""))/100,H30*AH30)) -> 10 | AV30: =IF(AG30="",0,IF(ISTEXT(AG30),H30*VALUE(SUBSTITUTE(AG30,"%",""))/100,H30*AG30)) -> 10
A31: R-1-4-11002 | C31: 30 | D31: ROLO DE CARGA Ø152 x 530 6305 - 30/25 | E31: 3723 | F31: 1 | G31: 16 | H31: =Tabela1[[#This Row],[PESO UNI]]*Tabela1[[#This Row],[QTE]] -> 480 | I31: 0 | J31: P202 | K31: ROLOS | L31: P-202 | M31: 46162 | N31: MDE | Q31: =Tabela1[[#This Row],[QTDE/ Fabricação]]-Tabela1[[#This Row],[QTE]] -> -30 | R31: =IFERROR(H31*((AA31*0.25)+(AC31*0.25)+(AD31*0.225)+(AE31*0.225)+(AF31*0.05)),"") -> 480 | S31: =IFERROR(H31*AG31,"") -> 480 | T31: =IFERROR(S31-H31,"") -> 0 | U31: =IFERROR(SUMIF('LISTA DE EMBARQUE'!B:B,MICRO!E:E,'LISTA DE EMBARQUE'!G:G),"") -> 30 | V31: =IFERROR(VLOOKUP(Tabela1[[#This Row],[COD.MDE]],'LISTA DE EMBARQUE'!B:L,11,0),"") -> 1 | W31: =IFERROR(VLOOKUP(Tabela1[[#This Row],[COD.MDE]],'LISTA DE EMBARQUE'!B:M,12,0),"") -> 46049 | X31: =IFERROR(Tabela1[[#This Row],[QIANTIDADE EXPEDIDA]]*Tabela1[[#This Row],[PESO UNI]],"") -> 480 | Y31: =U31-C31 -> 0 | Z31: =Tabela1[[#This Row],[PESO TOTAL]]-Tabela1[[#This Row],[Peso Expedido]] -> 0 | AA31: 1 | AB31: 1 | AC31: 1 | AD31: 1 | AE31: 1 | AF31: 1 | AG31: 1 | AH31: 1 | AI31: =IF(Z31<=0,"ok","") -> ok | AK31: =Tabela1[[#This Row],[Coluna1]]&Tabela1[[#This Row],[PEDIDO]] -> P-202 | AO31: =A31&"/"&J31 -> R-1-4-11002/P202 | AP31: =Tabela1[[#This Row],[TAG]]&Tabela1[[#This Row],[PEDIDO]]&Tabela1[[#This Row],[PRODUTO]] -> P202P-202ROLOS | AQ31: =Tabela1[[#This Row],[PRODUTO]]&Tabela1[[#This Row],[TAG]] -> ROLOSP202 | AR31: =Tabela1[[#This Row],[PEDIDO]]&Tabela1[[#This Row],[PRODUTO]] -> P-202ROLOS | AS31: =IF(AF31="",0,IF(ISTEXT(AF31),H31*VALUE(SUBSTITUTE(AF31,"%",""))/100,H31*AF31))-Tabela1[[#This Row],[PRONTO ACABADO2]] -> 0 | AT31: =IF(AG31="",0,IF(ISTEXT(AG31),H31*VALUE(SUBSTITUTE(AG31,"%",""))/100,H31*AG31))-Tabela1[[#This Row],[PESO EXPEDIDO2]] -> 0 | AU31: =IF(AH31="",0,IF(ISTEXT(AH31),H31*VALUE(SUBSTITUTE(AH31,"%",""))/100,H31*AH31)) -> 480 | AV31: =IF(AG31="",0,IF(ISTEXT(AG31),H31*VALUE(SUBSTITUTE(AG31,"%",""))/100,H31*AG31)) -> 480
